Workbook

Sheet Resumen
A1: PRESUPUESTO MENSUAL — DUBAI | D1: 0.24
A3: INGRESOS
A4: Salary 1 | B4: AED | C4: 25000
A5: Salary 2 | B5: AED | C5: 5000
A6: Adicional | B6: AED | C6: 1800
A7: TOTAL INGRESOS | C7: =SUM(C4:C6) -> 31800
A9: PREVISION GASTOS FIJOS
A10: Concepto | B10: AED | C10: EUR
A11: Alquiler Piso | B11: 8000 | C11: =B11*$D$1 -> 1920
A12: Compra Mensual | B12: 2800 | C12: =B12*$D$1 -> 672
A13: Coche (préstamo/pago) | B13: 2150 | C13: =B13*$D$1 -> 516
A14: DEWA (electricidad) | B14: 1200 | C14: =B14*$D$1 -> 288
A15: Gasolina y Salik | B15: 1000 | C15: =B15*$D$1 -> 240
A16: Seguro Bea | B16: 750 | C16: =B16*$D$1 -> 180
A17: Multas | B17: 500 | C17: =B17*$D$1 -> 120
A18: Nanny/Maid | B18: 0 | C18: =B18*$D$1 -> 0
A19: Móviles | B19: 320 | C19: =B19*$D$1 -> 76.8
A20: Internet | B20: 400 | C20: =B20*$D$1 -> 96
A21: Seguro Coche | B21: 300 | C21: =B21*$D$1 -> 72
A22: Visado Bea | B22: 200 | C22: =B22*$D$1 -> 48
... A25: Car Wash | B25: 100 | C25: =B25*$D$1 -> 24
A26: TOTAL GASTOS FIJOS | B26: =SUM(B11:B25) -> 18020 | C26: =SUM(C11:C25) -> 4324.8
A28: DISTRIBUCIÓN DEL INGRESO
A29: Total Ingresos | B29: =C7 -> 31800 | C29: =B29*$D$1 -> 7632
A30: (-) Gastos Fijos | B30: =B26 -> 18020 | C30: =C26 -> 4324.8
A31: (-) Ahorros | B31: =Ahorros!C14 -> 10800 | C31: =B31*$D$1 -> 2592
A32: = Disponible para Gastar | B32: =B29-B30-B31 -> 2980 | C32: =C29-C30-C31 -> 715.2
A34: RESUMEN ANUAL — GASTOS VARIABLES
A35: Mes | B35: Presupuesto | C35: Gastado | D35: Restante
A36: Enero | B36: =Resumen!$B$32 -> 2980 | C36: =Enero!C32 -> 0 | D36: =B36-C36 -> 2980
A37: Febrero | B37: =Resumen!$B$32 -> 2980 | C37: =Febrero!C32 -> 0 | D37: =B37-C37 -> 2980
A38: Marzo | B38: =Resumen!$B$32 -> 2980 | C38: =Marzo!C32 -> 0 | D38: =B38-C38 -> 2980
A39: Abril | B39: =Resumen!$B$32 -> 2980 | C39: =Abril!C32 -> 23465.167 | D39: =B39-C39 -> -20485.167
A40: Mayo | B40: =Resumen!$B$32 -> 2980 | C40: =Mayo!C32 -> 78371.572 | D40: =B40-C40 -> -75391.572
A41: Junio | B41: =Resumen!$B$32 -> 2980 | C41: =Junio!C32 -> 25618.3 | D41: =B41-C41 -> -22638.3
A42: Julio | B42: =Resumen!$B$32 -> 2980 | C42: =Julio!C32 -> 17112.102 | D42: =B42-C42 -> -14132.102
A43: Agosto | B43: =Resumen!$B$32 -> 2980 | C43: =Agosto!C32 -> 0 | D43: =B43-C43 -> 2980
A44: Septiembre | B44: =Resumen!$B$32 -> 2980 | C44: =Septiembre!C32 -> 0 | D44: =B44-C44 -> 2980
A45: Octubre | B45: =Resumen!$B$32 -> 2980 | C45: =Octubre!C32 -> 0 | D45: =B45-C45 -> 2980
A46: Noviembre | B46: =Resumen!$B$32 -> 2980 | C46: =Noviembre!C32 -> 0 | D46: =B46-C46 -> 2980
...

Sheet Ahorros
A1: AHORROS E INVERSIONES
A3: CUENTAS DE AHORRO
A4: Cuenta | B4: Objetivo | C4: Contribución | D4: Saldo Inicial | E4: Saldo Final | F4: Saldo Final €
A5: Cuenta Corriente | B5: 0 | C5: 3000 | D5: 0 | E5: =C5+D5 -> 3000 | F5: =E5*Resumen!$D$1 -> 720
A6: Cuenta Inversiones | B6: 0 | C6: 6000 | D6: 0 | E6: =C6+D6 -> 6000 | F6: =E6*Resumen!$D$1 -> 1440
A7: Otros 1 | B7: 0 | C7: 0 | D7: 0 | E7: =C7+D7 -> 0 | F7: =E7*Resumen!$D$1 -> 0
A8: Otros 2 | B8: 0 | C8: 0 | D8: 0 | E8: =C8+D8 -> 0 | F8: =E8*Resumen!$D$1 -> 0
A9: Otros 3 | B9: 0 | C9: 0 | D9: 0 | E9: =C9+D9 -> 0 | F9: =E9*Resumen!$D$1 -> 0
A10: FONDOS DE EMERGENCIA
A11: Emergencias varias | B11: 0 | C11: 400 | D11: 0 | E11: =C11+D11 -> 400 | F11: =E11*Resumen!$D$1 -> 96
A12: Emergencia Médica | B12: 0 | C12: 1000 | D12: 0 | E12: =C12+D12 -> 1000 | F12: =E12*Resumen!$D$1 -> 240
A13: Emergencia Coche | B13: 0 | C13: 400 | D13: 0 | E13: =C13+D13 -> 400 | F13: =E13*Resumen!$D$1 -> 96
A14: TOTAL AHORRO | C14: =SUM(C5:C9)+SUM(C11:C13) -> 10800 | D14: =SUM(D5:D9)+SUM(D11:D13) -> 0 | E14: =SUM(E5:E9)+SUM(E11:E13) -> 10800 | F14: =E14*Resumen!$D$1 -> 2592
A16: PROVISIONES (Sinking Funds)
A17: Concepto | B17: Objetivo | C17: Contribución | D17: Saldo Inicial | E17: Saldo Final | F17: Saldo Final €
A18: Medicinas y gastos médicos | B18: 0 | C18: 0 | D18: 0 | E18: =C18+D18 -> 0 | F18: =E18*Resumen!$D$1 -> 0
A19: TOTAL PROVISIONES | C19: =SUM(C18:C18) -> 0 | D19: =SUM(D18:D18) -> 0 | E19: =SUM(E18:E18) -> 0 | F19: =E19*Resumen!$D$1 -> 0

Sheet Enero
A1: INGRESOS MENSUALES
A2: Concepto | C2: Total AED | D2: Total EUR
A3: Salario Santi | C3: =Resumen!$C$4 -> 25000 | D3: =C3*Resumen!$D$1 -> 6000
A4: Salario Bea | C4: =D4/Resumen!$D$1 -> 5000 | D4: =Resumen!$C$5*Resumen!$D$1 -> 1200
A5: Ingresos extra | C5: =D5/Resumen!$D$1 -> 1800 | D5: =Resumen!$C$6*Resumen!$D$1 -> 432
A6: TOTAL INGRESOS | C6: =SUM(C3:C5) -> 31800 | D6: =SUM(D3:D5) -> 7632
A7: BALANCE (Ingreso - Gasto) | C7: =C6-C32 -> 31800 | D7: =D6-D32 -> 7632
A9: GASTOS MENSUALES
A11: RESUMEN POR CATEGORÍA
A12: Categoría | B12: Nº Gastos | C12: Total AED | D12: Total EUR
A13: Restaurantes | B13: =COUNTIF(B37:B56,A13)+COUNTIF(G37:G56,A13)+COUNTIF(L37:L56,A13)+COUNTIF(Q37:Q56,A13)+COUNTIF(V37:V56,A13) -> 0 | C13: =SUMIF(B37:B56,A13,C37:C56)+SUMIF(G37:G56,A13,H37:H56)+SUMIF(L37:L56,A13,M37:M56)+SUMIF(Q37:Q56,A13,R37:R56)+SUMIF(V37:V56,A13,W37:W56)+(SUMIF(B37:B56,A13,D37:D56)+SUMIF(G37:G56,A13,I37:I56)+SUMIF(L37:L56,A13,N37:N56)+SUMIF(Q37:Q56,A13,S37:S56)+SUMIF(V37:V56,A13,X37:X56))/Resumen!$D$1 -> 0 | D13: =C13*Resumen!$D$1 -> 0
A14: Ocio | B14: =COUNTIF(B37:B56,A14)+COUNTIF(G37:G56,A14)+COUNTIF(L37:L56,A14)+COUNTIF(Q37:Q56,A14)+COUNTIF(V37:V56,A14) -> 0 | C14: =SUMIF(B37:B56,A14,C37:C56)+SUMIF(G37:G56,A14,H37:H56)+SUMIF(L37:L56,A14,M37:M56)+SUMIF(Q37:Q56,A14,R37:R56)+SUMIF(V37:V56,A14,W37:W56)+(SUMIF(B37:B56,A14,D37:D56)+SUMIF(G37:G56,A14,I37:I56)+SUMIF(L37:L56,A14,N37:N56)+SUMIF(Q37:Q56,A14,S37:S56)+SUMIF(V37:V56,A14,X37:X56))/Resumen!$D$1 -> 0 | D14: =C14*Resumen!$D$1 -> 0
A15: Compras | B15: 0 | C15: 0 | D15: =C15*Resumen!$D$1 -> 0
A16: Salud | B16: =COUNTIF(B37:B56,A16)+COUNTIF(G37:G56,A16)+COUNTIF(L37:L56,A16)+COUNTIF(Q37:Q56,A16)+COUNTIF(V37:V56,A16) -> 0 | C16: =SUMIF(B37:B56,A16,C37:C56)+SUMIF(G37:G56,A16,H37:H56)+SUMIF(L37:L56,A16,M37:M56)+SUMIF(Q37:Q56,A16,R37:R56)+SUMIF(V37:V56,A16,W37:W56)+(SUMIF(B37:B56,A16,D37:D56)+SUMIF(G37:G56,A16,I37:I56)+SUMIF(L37:L56,A16,N37:N56)+SUMIF(Q37:Q56,A16,S37:S56)+SUMIF(V37:V56,A16,X37:X56))/Resumen!$D$1 -> 0 | D16: =C16*Resumen!$D$1 -> 0
A17: Viajes | B17: =COUNTIF(B37:B56,A17)+COUNTIF(G37:G56,A17)+COUNTIF(L37:L56,A17)+COUNTIF(Q37:Q56,A17)+COUNTIF(V37:V56,A17) -> 0 | C17: =SUMIF(B37:B56,A17,C37:C56)+SUMIF(G37:G56,A17,H37:H56)+SUMIF(L37:L56,A17,M37:M56)+SUMIF(Q37:Q56,A17,R37:R56)+SUMIF(V37:V56,A17,W37:W56)+(SUMIF(B37:B56,A17,D37:D56)+SUMIF(G37:G56,A17,I37:I56)+SUMIF(L37:L56,A17,N37:N56)+SUMIF(Q37:Q56,A17,S37:S56)+SUMIF(V37:V56,A17,X37:X56))/Resumen!$D$1 -> 0 | D17: =C17*Resumen!$D$1 -> 0
A18: Santi | B18: =COUNTIF(B37:B56,A18)+COUNTIF(G37:G56,A18)+COUNTIF(L37:L56,A18)+COUNTIF(Q37:Q56,A18)+COUNTIF(V37:V56,A18) -> 0 | C18: =SUMIF(B37:B56,A18,C37:C56)+SUMIF(G37:G56,A18,H37:H56)+SUMIF(L37:L56,A18,M37:M56)+SUMIF(Q37:Q56,A18,R37:R56)+SUMIF(V37:V56,A18,W37:W56)+(SUMIF(B37:B56,A18,D37:D56)+SUMIF(G37:G56,A18,I37:I56)+SUMIF(L37:L56,A18,N37:N56)+SUMIF(Q37:Q56,A18,S37:S56)+SUMIF(V37:V56,A18,X37:X56))/Resumen!$D$1 -> 0 | D18: =C18*Resumen!$D$1 -> 0
A19: Bea | B19: =COUNTIF(B37:B56,A19)+COUNTIF(G37:G56,A19)+COUNTIF(L37:L56,A19)+COUNTIF(Q37:Q56,A19)+COUNTIF(V37:V56,A19) -> 0 | C19: =SUMIF(B37:B56,A19,C37:C56)+SUMIF(G37:G56,A19,H37:H56)+SUMIF(L37:L56,A19,M37:M56)+SUMIF(Q37:Q56,A19,R37:R56)+SUMIF(V37:V56,A19,W37:W56)+(SUMIF(B37:B56,A19,D37:D56)+SUMIF(G37:G56,A19,I37:I56)+SUMIF(L37:L56,A19,N37:N56)+SUMIF(Q37:Q56,A19,S37:S56)+SUMIF(V37:V56,A19,X37:X56))/Resumen!$D$1 -> 0 | D19: =C19*Resumen!$D$1 -> 0
A20: Personal | B20: =COUNTIF(B37:B56,A20)+COUNTIF(G37:G56,A20)+COUNTIF(L37:L56,A20)+COUNTIF(Q37:Q56,A20)+COUNTIF(V37:V56,A20) -> 0 | C20: =SUMIF(B37:B56,A20,C37:C56)+SUMIF(G37:G56,A20,H37:H56)+SUMIF(L37:L56,A20,M37:M56)+SUMIF(Q37:Q56,A20,R37:R56)+SUMIF(V37:V56,A20,W37:W56)+(SUMIF(B37:B56,A20,D37:D56)+SUMIF(G37:G56,A20,I37:I56)+SUMIF(L37:L56,A20,N37:N56)+SUMIF(Q37:Q56,A20,S37:S56)+SUMIF(V37:V56,A20,X37:X56))/Resumen!$D$1 -> 0 | D20: =C20*Resumen!$D$1 -> 0
A21: Transporte | B21: =COUNTIF(B37:B56,A21)+COUNTIF(G37:G56,A21)+COUNTIF(L37:L56,A21)+COUNTIF(Q37:Q56,A21)+COUNTIF(V37:V56,A21) -> 0 | C21: =SUMIF(B37:B56,A21,C37:C56)+SUMIF(G37:G56,A21,H37:H56)+SUMIF(L37:L56,A21,M37:M56)+SUMIF(Q37:Q56,A21,R37:R56)+SUMIF(V37:V56,A21,W37:W56)+(SUMIF(B37:B56,A21,D37:D56)+SUMIF(G37:G56,A21,I37:I56)+SUMIF(L37:L56,A21,N37:N56)+SUMIF(Q37:Q56,A21,S37:S56)+SUMIF(V37:V56,A21,X37:X56))/Resumen!$D$1 -> 0 | D21: =C21*Resumen!$D$1 -> 0
A22: Regalos | B22: =COUNTIF(B37:B56,A22)+COUNTIF(G37:G56,A22)+COUNTIF(L37:L56,A22)+COUNTIF(Q37:Q56,A22)+COUNTIF(V37:V56,A22) -> 0 | C22: =SUMIF(B37:B56,A22,C37:C56)+SUMIF(G37:G56,A22,H37:H56)+SUMIF(L37:L56,A22,M37:M56)+SUMIF(Q37:Q56,A22,R37:R56)+SUMIF(V37:V56,A22,W37:W56)+(SUMIF(B37:B56,A22,D37:D56)+SUMIF(G37:G56,A22,I37:I56)+SUMIF(L37:L56,A22,N37:N56)+SUMIF(Q37:Q56,A22,S37:S56)+SUMIF(V37:V56,A22,X37:X56))/Resumen!$D$1 -> 0 | D22: =C22*Resumen!$D$1 -> 0
A23: Alquiler piso | B23: =COUNTIF(B37:B56,A23)+COUNTIF(G37:G56,A23)+COUNTIF(L37:L56,A23)+COUNTIF(Q37:Q56,A23)+COUNTIF(V37:V56,A23) -> 0 | C23: =SUMIF(B37:B56,A23,C37:C56)+SUMIF(G37:G56,A23,H37:H56)+SUMIF(L37:L56,A23,M37:M56)+SUMIF(Q37:Q56,A23,R37:R56)+SUMIF(V37:V56,A23,W37:W56)+(SUMIF(B37:B56,A23,D37:D56)+SUMIF(G37:G56,A23,I37:I56)+SUMIF(L37:L56,A23,N37:N56)+SUMIF(Q37:Q56,A23,S37:S56)+SUMIF(V37:V56,A23,X37:X56))/Resumen!$D$1 -> 0 | D23: =C23*Resumen!$D$1 -> 0
A24: Mudanza | B24: =COUNTIF(B37:B56,A24)+COUNTIF(G37:G56,A24)+COUNTIF(L37:L56,A24)+COUNTIF(Q37:Q56,A24)+COUNTIF(V37:V56,A24) -> 0 | C24: =SUMIF(B37:B56,A24,C37:C56)+SUMIF(G37:G56,A24,H37:H56)+SUMIF(L37:L56,A24,M37:M56)+SUMIF(Q37:Q56,A24,R37:R56)+SUMIF(V37:V56,A24,W37:W56)+(SUMIF(B37:B56,A24,D37:D56)+SUMIF(G37:G56,A24,I37:I56)+SUMIF(L37:L56,A24,N37:N56)+SUMIF(Q37:Q56,A24,S37:S56)+SUMIF(V37:V56,A24,X37:X56))/Resumen!$D$1 -> 0 | D24: =C24*Resumen!$D$1 -> 0
A25: Tasas | B25: =COUNTIF(B37:B56,A25)+COUNTIF(G37:G56,A25)+COUNTIF(L37:L56,A25)+COUNTIF(Q37:Q56,A25)+COUNTIF(V37:V56,A25) -> 0 | C25: =SUMIF(B37:B56,A25,C37:C56)+SUMIF(G37:G56,A25,H37:H56)+SUMIF(L37:L56,A25,M37:M56)+SUMIF(Q37:Q56,A25,R37:R56)+SUMIF(V37:V56,A25,W37:W56)+(SUMIF(B37:B56,A25,D37:D56)+SUMIF(G37:G56,A25,I37:I56)+SUMIF(L37:L56,A25,N37:N56)+SUMIF(Q37:Q56,A25,S37:S56)+SUMIF(V37:V56,A25,X37:X56))/Resumen!$D$1 -> 0 | D25: =C25*Resumen!$D$1 -> 0
A26: Suministros piso | B26: =COUNTIF(B37:B56,A26)+COUNTIF(G37:G56,A26)+COUNTIF(L37:L56,A26)+COUNTIF(Q37:Q56,A26)+COUNTIF(V37:V56,A26) -> 0 | C26: =SUMIF(B37:B56,A26,C37:C56)+SUMIF(G37:G56,A26,H37:H56)+SUMIF(L37:L56,A26,M37:M56)+SUMIF(Q37:Q56,A26,R37:R56)+SUMIF(V37:V56,A26,W37:W56)+(SUMIF(B37:B56,A26,D37:D56)+SUMIF(G37:G56,A26,I37:I56)+SUMIF(L37:L56,A26,N37:N56)+SUMIF(Q37:Q56,A26,S37:S56)+SUMIF(V37:V56,A26,X37:X56))/Resumen!$D$1 -> 0 | D26: =C26*Resumen!$D$1 -> 0
A27: Otros | B27: =COUNTIF(B37:B56,A27)+COUNTIF(G37:G56,A27)+COUNTIF(L37:L56,A27)+COUNTIF(Q37:Q56,A27)+COUNTIF(V37:V56,A27) -> 0 | C27: =SUMIF(B37:B56,A27,C37:C56)+SUMIF(G37:G56,A27,H37:H56)+SUMIF(L37:L56,A27,M37:M56)+SUMIF(Q37:Q56,A27,R37:R56)+SUMIF(V37:V56,A27,W37:W56)+(SUMIF(B37:B56,A27,D37:D56)+SUMIF(G37:G56,A27,I37:I56)+SUMIF(L37:L56,A27,N37:N56)+SUMIF(Q37:Q56,A27,S37:S56)+SUMIF(V37:V56,A27,X37:X56))/Resumen!$D$1 -> 0 | D27: =C27*Resumen!$D$1 -> 0
A28: Hogar | B28: =COUNTIF(B37:B56,A28)+COUNTIF(G37:G56,A28)+COUNTIF(L37:L56,A28)+COUNTIF(Q37:Q56,A28)+COUNTIF(V37:V56,A28) -> 0 | C28: =SUMIF(B37:B56,A28,C37:C56)+SUMIF(G37:G56,A28,H37:H56)+SUMIF(L37:L56,A28,M37:M56)+SUMIF(Q37:Q56,A28,R37:R56)+SUMIF(V37:V56,A28,W37:W56)+(SUMIF(B37:B56,A28,D37:D56)+SUMIF(G37:G56,A28,I37:I56)+SUMIF(L37:L56,A28,N37:N56)+SUMIF(Q37:Q56,A28,S37:S56)+SUMIF(V37:V56,A28,X37:X56))/Resumen!$D$1 -> 0 | D28: =C28*Resumen!$D$1 -> 0
A29: Delivery | B29: =COUNTIF(B37:B56,A29)+COUNTIF(G37:G56,A29)+COUNTIF(L37:L56,A29)+COUNTIF(Q37:Q56,A29)+COUNTIF(V37:V56,A29) -> 0 | C29: =SUMIF(B37:B56,A29,C37:C56)+SUMIF(G37:G56,A29,H37:H56)+SUMIF(L37:L56,A29,M37:M56)+SUMIF(Q37:Q56,A29,R37:R56)+SUMIF(V37:V56,A29,W37:W56)+(SUMIF(B37:B56,A29,D37:D56)+SUMIF(G37:G56,A29,I37:I56)+SUMIF(L37:L56,A29,N37:N56)+SUMIF(Q37:Q56,A29,S37:S56)+SUMIF(V37:V56,A29,X37:X56))/Resumen!$D$1 -> 0 | D29: =C29*Resumen!$D$1 -> 0
A30: Supermercado | B30: =COUNTIF(B37:B56,A30)+COUNTIF(G37:G56,A30)+COUNTIF(L37:L56,A30)+COUNTIF(Q37:Q56,A30)+COUNTIF(V37:V56,A30) -> 0 | C30: =SUMIF(B37:B56,A30,C37:C56)+SUMIF(G37:G56,A30,H37:H56)+SUMIF(L37:L56,A30,M37:M56)+SUMIF(Q37:Q56,A30,R37:R56)+SUMIF(V37:V56,A30,W37:W56)+(SUMIF(B37:B56,A30,D37:D56)+SUMIF(G37:G56,A30,I37:I56)+SUMIF(L37:L56,A30,N37:N56)+SUMIF(Q37:Q56,A30,S37:S56)+SUMIF(V37:V56,A30,X37:X56))/Resumen!$D$1 -> 0 | D30: =C30*Resumen!$D$1 -> 0
A31: Suscripciones | B31: =COUNTIF(B37:B56,A31)+COUNTIF(G37:G56,A31)+COUNTIF(L37:L56,A31)+COUNTIF(Q37:Q56,A31)+COUNTIF(V37:V56,A31) -> 0 | C31: =SUMIF(B37:B56,A31,C37:C56)+SUMIF(G37:G56,A31,H37:H56)+SUMIF(L37:L56,A31,M37:M56)+SUMIF(Q37:Q56,A31,R37:R56)+SUMIF(V37:V56,A31,W37:W56)+(SUMIF(B37:B56,A31,D37:D56)+SUMIF(G37:G56,A31,I37:I56)+SUMIF(L37:L56,A31,N37:N56)+SUMIF(Q37:Q56,A31,S37:S56)+SUMIF(V37:V56,A31,X37:X56))/Resumen!$D$1 -> 0 | D31: =C31*Resumen!$D$1 -> 0
A32: TOTAL MES | B32: =SUM(B13:B31) -> 0 | C32: =SUM(C13:C31) -> 0 | D32: =SUM(D13:D31) -> 0
A34: REGISTRO SEMANAL
A35: SEMANA 1 | F35: SEMANA 2 | K35: SEMANA 3 | P35: SEMANA 4 | U35: SEMANA 5
A36: Concepto | B36: Categ. | C36: AED | D36: EUR | E36: Fecha | F36: Concepto | G36: Categ. | H36: AED | I36: EUR | J36: Fecha | K36: Concepto | L36: Categ. | M36: AED | N36: EUR | O36: Fecha | P36: Concepto | Q36: Categ. | R36: AED | S36: EUR | T36: Fecha | U36: Concepto | V36: Categ. | W36: AED | X36: EUR
A37: Sofa y mesa café | B37: Compras | C37: 821.61
A57: TOTAL | C57: =SUM(C37:C56)+SUM(D37:D56)/Resumen!$D$1 -> 821.61 | D57: =SUM(D37:D56)+SUM(C37:C56)*Resumen!$D$1 -> 197.1864 | H57: =SUM(H37:H56)+SUM(I37:I56)/Resumen!$D$1 -> 0 | I57: =SUM(I37:I56)+SUM(H37:H56)*Resumen!$D$1 -> 0 | M57: =SUM(M37:M56)+SUM(N37:N56)/Resumen!$D$1 -> 0 | N57: =SUM(N37:N56)+SUM(M37:M56)*Resumen!$D$1 -> 0 | R57: =SUM(R37:R56)+SUM(S37:S56)/Resumen!$D$1 -> 0 | S57: =SUM(S37:S56)+SUM(R37:R56)*Resumen!$D$1 -> 0 | W57: =SUM(W37:W56)+SUM(X37:X56)/Resumen!$D$1 -> 0 | X57: =SUM(X37:X56)+SUM(W37:W56)*Resumen!$D$1 -> 0
A58: RESTANTE | C58: =Resumen!$B$32-C57 -> 2158.39 | D58: =Resumen!$C$32-D57 -> 518.0136 | H58: =C58-H57 -> 2158.39 | I58: =D58-I57 -> 518.0136 | M58: =H58-M57 -> 2158.39 | N58: =I58-N57 -> 518.0136 | R58: =M58-R57 -> 2158.39 | S58: =N58-S57 -> 518.0136 | W58: =R58-W57 -> 2158.39 | X58: =S58-X57 -> 518.0136

Sheet Febrero
A1: INGRESOS MENSUALES
A2: Concepto | C2: Total AED | D2: Total EUR
A3: Salario Santi | C3: =Resumen!$C$4 -> 25000 | D3: =C3*Resumen!$D$1 -> 6000
A4: Salario Bea | C4: =D4/Resumen!$D$1 -> 5000 | D4: =Resumen!$C$5*Resumen!$D$1 -> 1200
A5: Ingresos extra | C5: =D5/Resumen!$D$1 -> 1800 | D5: =Resumen!$C$6*Resumen!$D$1 -> 432
A6: TOTAL INGRESOS | C6: =SUM(C3:C5) -> 31800 | D6: =SUM(D3:D5) -> 7632
A7: BALANCE (Ingreso - Gasto) | C7: =C6-C32 -> 31800 | D7: =D6-D32 -> 7632
A9: GASTOS MENSUALES
A11: RESUMEN POR CATEGORÍA
A12: Categoría | B12: Nº Gastos | C12: Total AED | D12: Total EUR
A13: Restaurantes | B13: =COUNTIF(B37:B56,A13)+COUNTIF(G37:G56,A13)+COUNTIF(L37:L56,A13)+COUNTIF(Q37:Q56,A13)+COUNTIF(V37:V56,A13) -> 0 | C13: =SUMIF(B37:B56,A13,C37:C56)+SUMIF(G37:G56,A13,H37:H56)+SUMIF(L37:L56,A13,M37:M56)+SUMIF(Q37:Q56,A13,R37:R56)+SUMIF(V37:V56,A13,W37:W56)+(SUMIF(B37:B56,A13,D37:D56)+SUMIF(G37:G56,A13,I37:I56)+SUMIF(L37:L56,A13,N37:N56)+SUMIF(Q37:Q56,A13,S37:S56)+SUMIF(V37:V56,A13,X37:X56))/Resumen!$D$1 -> 0 | D13: =C13*Resumen!$D$1 -> 0
A14: Ocio | B14: =COUNTIF(B37:B56,A14)+COUNTIF(G37:G56,A14)+COUNTIF(L37:L56,A14)+COUNTIF(Q37:Q56,A14)+COUNTIF(V37:V56,A14) -> 0 | C14: =SUMIF(B37:B56,A14,C37:C56)+SUMIF(G37:G56,A14,H37:H56)+SUMIF(L37:L56,A14,M37:M56)+SUMIF(Q37:Q56,A14,R37:R56)+SUMIF(V37:V56,A14,W37:W56)+(SUMIF(B37:B56,A14,D37:D56)+SUMIF(G37:G56,A14,I37:I56)+SUMIF(L37:L56,A14,N37:N56)+SUMIF(Q37:Q56,A14,S37:S56)+SUMIF(V37:V56,A14,X37:X56))/Resumen!$D$1 -> 0 | D14: =C14*Resumen!$D$1 -> 0
A15: Compras | B15: =COUNTIF(B37:B56,A15)+COUNTIF(G37:G56,A15)+COUNTIF(L37:L56,A15)+COUNTIF(Q37:Q56,A15)+COUNTIF(V37:V56,A15) -> 0 | C15: =SUMIF(B37:B56,A15,C37:C56)+SUMIF(G37:G56,A15,H37:H56)+SUMIF(L37:L56,A15,M37:M56)+SUMIF(Q37:Q56,A15,R37:R56)+SUMIF(V37:V56,A15,W37:W56)+(SUMIF(B37:B56,A15,D37:D56)+SUMIF(G37:G56,A15,I37:I56)+SUMIF(L37:L56,A15,N37:N56)+SUMIF(Q37:Q56,A15,S37:S56)+SUMIF(V37:V56,A15,X37:X56))/Resumen!$D$1 -> 0 | D15: =C15*Resumen!$D$1 -> 0
A16: Salud | B16: =COUNTIF(B37:B56,A16)+COUNTIF(G37:G56,A16)+COUNTIF(L37:L56,A16)+COUNTIF(Q37:Q56,A16)+COUNTIF(V37:V56,A16) -> 0 | C16: =SUMIF(B37:B56,A16,C37:C56)+SUMIF(G37:G56,A16,H37:H56)+SUMIF(L37:L56,A16,M37:M56)+SUMIF(Q37:Q56,A16,R37:R56)+SUMIF(V37:V56,A16,W37:W56)+(SUMIF(B37:B56,A16,D37:D56)+SUMIF(G37:G56,A16,I37:I56)+SUMIF(L37:L56,A16,N37:N56)+SUMIF(Q37:Q56,A16,S37:S56)+SUMIF(V37:V56,A16,X37:X56))/Resumen!$D$1 -> 0 | D16: =C16*Resumen!$D$1 -> 0
A17: Viajes | B17: =COUNTIF(B37:B56,A17)+COUNTIF(G37:G56,A17)+COUNTIF(L37:L56,A17)+COUNTIF(Q37:Q56,A17)+COUNTIF(V37:V56,A17) -> 0 | C17: =SUMIF(B37:B56,A17,C37:C56)+SUMIF(G37:G56,A17,H37:H56)+SUMIF(L37:L56,A17,M37:M56)+SUMIF(Q37:Q56,A17,R37:R56)+SUMIF(V37:V56,A17,W37:W56)+(SUMIF(B37:B56,A17,D37:D56)+SUMIF(G37:G56,A17,I37:I56)+SUMIF(L37:L56,A17,N37:N56)+SUMIF(Q37:Q56,A17,S37:S56)+SUMIF(V37:V56,A17,X37:X56))/Resumen!$D$1 -> 0 | D17: =C17*Resumen!$D$1 -> 0
A18: Santi | B18: =COUNTIF(B37:B56,A18)+COUNTIF(G37:G56,A18)+COUNTIF(L37:L56,A18)+COUNTIF(Q37:Q56,A18)+COUNTIF(V37:V56,A18) -> 0 | C18: =SUMIF(B37:B56,A18,C37:C56)+SUMIF(G37:G56,A18,H37:H56)+SUMIF(L37:L56,A18,M37:M56)+SUMIF(Q37:Q56,A18,R37:R56)+SUMIF(V37:V56,A18,W37:W56)+(SUMIF(B37:B56,A18,D37:D56)+SUMIF(G37:G56,A18,I37:I56)+SUMIF(L37:L56,A18,N37:N56)+SUMIF(Q37:Q56,A18,S37:S56)+SUMIF(V37:V56,A18,X37:X56))/Resumen!$D$1 -> 0 | D18: =C18*Resumen!$D$1 -> 0
A19: Bea | B19: =COUNTIF(B37:B56,A19)+COUNTIF(G37:G56,A19)+COUNTIF(L37:L56,A19)+COUNTIF(Q37:Q56,A19)+COUNTIF(V37:V56,A19) -> 0 | C19: =SUMIF(B37:B56,A19,C37:C56)+SUMIF(G37:G56,A19,H37:H56)+SUMIF(L37:L56,A19,M37:M56)+SUMIF(Q37:Q56,A19,R37:R56)+SUMIF(V37:V56,A19,W37:W56)+(SUMIF(B37:B56,A19,D37:D56)+SUMIF(G37:G56,A19,I37:I56)+SUMIF(L37:L56,A19,N37:N56)+SUMIF(Q37:Q56,A19,S37:S56)+SUMIF(V37:V56,A19,X37:X56))/Resumen!$D$1 -> 0 | D19: =C19*Resumen!$D$1 -> 0
A20: Personal | B20: =COUNTIF(B37:B56,A20)+COUNTIF(G37:G56,A20)+COUNTIF(L37:L56,A20)+COUNTIF(Q37:Q56,A20)+COUNTIF(V37:V56,A20) -> 0 | C20: =SUMIF(B37:B56,A20,C37:C56)+SUMIF(G37:G56,A20,H37:H56)+SUMIF(L37:L56,A20,M37:M56)+SUMIF(Q37:Q56,A20,R37:R56)+SUMIF(V37:V56,A20,W37:W56)+(SUMIF(B37:B56,A20,D37:D56)+SUMIF(G37:G56,A20,I37:I56)+SUMIF(L37:L56,A20,N37:N56)+SUMIF(Q37:Q56,A20,S37:S56)+SUMIF(V37:V56,A20,X37:X56))/Resumen!$D$1 -> 0 | D20: =C20*Resumen!$D$1 -> 0
A21: Transporte | B21: =COUNTIF(B37:B56,A21)+COUNTIF(G37:G56,A21)+COUNTIF(L37:L56,A21)+COUNTIF(Q37:Q56,A21)+COUNTIF(V37:V56,A21) -> 0 | C21: =SUMIF(B37:B56,A21,C37:C56)+SUMIF(G37:G56,A21,H37:H56)+SUMIF(L37:L56,A21,M37:M56)+SUMIF(Q37:Q56,A21,R37:R56)+SUMIF(V37:V56,A21,W37:W56)+(SUMIF(B37:B56,A21,D37:D56)+SUMIF(G37:G56,A21,I37:I56)+SUMIF(L37:L56,A21,N37:N56)+SUMIF(Q37:Q56,A21,S37:S56)+SUMIF(V37:V56,A21,X37:X56))/Resumen!$D$1 -> 0 | D21: =C21*Resumen!$D$1 -> 0
A22: Regalos | B22: =COUNTIF(B37:B56,A22)+COUNTIF(G37:G56,A22)+COUNTIF(L37:L56,A22)+COUNTIF(Q37:Q56,A22)+COUNTIF(V37:V56,A22) -> 0 | C22: =SUMIF(B37:B56,A22,C37:C56)+SUMIF(G37:G56,A22,H37:H56)+SUMIF(L37:L56,A22,M37:M56)+SUMIF(Q37:Q56,A22,R37:R56)+SUMIF(V37:V56,A22,W37:W56)+(SUMIF(B37:B56,A22,D37:D56)+SUMIF(G37:G56,A22,I37:I56)+SUMIF(L37:L56,A22,N37:N56)+SUMIF(Q37:Q56,A22,S37:S56)+SUMIF(V37:V56,A22,X37:X56))/Resumen!$D$1 -> 0 | D22: =C22*Resumen!$D$1 -> 0
A23: Alquiler piso | B23: =COUNTIF(B37:B56,A23)+COUNTIF(G37:G56,A23)+COUNTIF(L37:L56,A23)+COUNTIF(Q37:Q56,A23)+COUNTIF(V37:V56,A23) -> 0 | C23: =SUMIF(B37:B56,A23,C37:C56)+SUMIF(G37:G56,A23,H37:H56)+SUMIF(L37:L56,A23,M37:M56)+SUMIF(Q37:Q56,A23,R37:R56)+SUMIF(V37:V56,A23,W37:W56)+(SUMIF(B37:B56,A23,D37:D56)+SUMIF(G37:G56,A23,I37:I56)+SUMIF(L37:L56,A23,N37:N56)+SUMIF(Q37:Q56,A23,S37:S56)+SUMIF(V37:V56,A23,X37:X56))/Resumen!$D$1 -> 0 | D23: =C23*Resumen!$D$1 -> 0
A24: Mudanza | B24: =COUNTIF(B37:B56,A24)+COUNTIF(G37:G56,A24)+COUNTIF(L37:L56,A24)+COUNTIF(Q37:Q56,A24)+COUNTIF(V37:V56,A24) -> 0 | C24: =SUMIF(B37:B56,A24,C37:C56)+SUMIF(G37:G56,A24,H37:H56)+SUMIF(L37:L56,A24,M37:M56)+SUMIF(Q37:Q56,A24,R37:R56)+SUMIF(V37:V56,A24,W37:W56)+(SUMIF(B37:B56,A24,D37:D56)+SUMIF(G37:G56,A24,I37:I56)+SUMIF(L37:L56,A24,N37:N56)+SUMIF(Q37:Q56,A24,S37:S56)+SUMIF(V37:V56,A24,X37:X56))/Resumen!$D$1 -> 0 | D24: =C24*Resumen!$D$1 -> 0
A25: Tasas | B25: =COUNTIF(B37:B56,A25)+COUNTIF(G37:G56,A25)+COUNTIF(L37:L56,A25)+COUNTIF(Q37:Q56,A25)+COUNTIF(V37:V56,A25) -> 0 | C25: =SUMIF(B37:B56,A25,C37:C56)+SUMIF(G37:G56,A25,H37:H56)+SUMIF(L37:L56,A25,M37:M56)+SUMIF(Q37:Q56,A25,R37:R56)+SUMIF(V37:V56,A25,W37:W56)+(SUMIF(B37:B56,A25,D37:D56)+SUMIF(G37:G56,A25,I37:I56)+SUMIF(L37:L56,A25,N37:N56)+SUMIF(Q37:Q56,A25,S37:S56)+SUMIF(V37:V56,A25,X37:X56))/Resumen!$D$1 -> 0 | D25: =C25*Resumen!$D$1 -> 0
A26: Suministros piso | B26: =COUNTIF(B37:B56,A26)+COUNTIF(G37:G56,A26)+COUNTIF(L37:L56,A26)+COUNTIF(Q37:Q56,A26)+COUNTIF(V37:V56,A26) -> 0 | C26: =SUMIF(B37:B56,A26,C37:C56)+SUMIF(G37:G56,A26,H37:H56)+SUMIF(L37:L56,A26,M37:M56)+SUMIF(Q37:Q56,A26,R37:R56)+SUMIF(V37:V56,A26,W37:W56)+(SUMIF(B37:B56,A26,D37:D56)+SUMIF(G37:G56,A26,I37:I56)+SUMIF(L37:L56,A26,N37:N56)+SUMIF(Q37:Q56,A26,S37:S56)+SUMIF(V37:V56,A26,X37:X56))/Resumen!$D$1 -> 0 | D26: =C26*Resumen!$D$1 -> 0
A27: Otros | B27: =COUNTIF(B37:B56,A27)+COUNTIF(G37:G56,A27)+COUNTIF(L37:L56,A27)+COUNTIF(Q37:Q56,A27)+COUNTIF(V37:V56,A27) -> 0 | C27: =SUMIF(B37:B56,A27,C37:C56)+SUMIF(G37:G56,A27,H37:H56)+SUMIF(L37:L56,A27,M37:M56)+SUMIF(Q37:Q56,A27,R37:R56)+SUMIF(V37:V56,A27,W37:W56)+(SUMIF(B37:B56,A27,D37:D56)+SUMIF(G37:G56,A27,I37:I56)+SUMIF(L37:L56,A27,N37:N56)+SUMIF(Q37:Q56,A27,S37:S56)+SUMIF(V37:V56,A27,X37:X56))/Resumen!$D$1 -> 0 | D27: =C27*Resumen!$D$1 -> 0
A28: Hogar | B28: =COUNTIF(B37:B56,A28)+COUNTIF(G37:G56,A28)+COUNTIF(L37:L56,A28)+COUNTIF(Q37:Q56,A28)+COUNTIF(V37:V56,A28) -> 0 | C28: =SUMIF(B37:B56,A28,C37:C56)+SUMIF(G37:G56,A28,H37:H56)+SUMIF(L37:L56,A28,M37:M56)+SUMIF(Q37:Q56,A28,R37:R56)+SUMIF(V37:V56,A28,W37:W56)+(SUMIF(B37:B56,A28,D37:D56)+SUMIF(G37:G56,A28,I37:I56)+SUMIF(L37:L56,A28,N37:N56)+SUMIF(Q37:Q56,A28,S37:S56)+SUMIF(V37:V56,A28,X37:X56))/Resumen!$D$1 -> 0 | D28: =C28*Resumen!$D$1 -> 0
A29: Delivery | B29: =COUNTIF(B37:B56,A29)+COUNTIF(G37:G56,A29)+COUNTIF(L37:L56,A29)+COUNTIF(Q37:Q56,A29)+COUNTIF(V37:V56,A29) -> 0 | C29: =SUMIF(B37:B56,A29,C37:C56)+SUMIF(G37:G56,A29,H37:H56)+SUMIF(L37:L56,A29,M37:M56)+SUMIF(Q37:Q56,A29,R37:R56)+SUMIF(V37:V56,A29,W37:W56)+(SUMIF(B37:B56,A29,D37:D56)+SUMIF(G37:G56,A29,I37:I56)+SUMIF(L37:L56,A29,N37:N56)+SUMIF(Q37:Q56,A29,S37:S56)+SUMIF(V37:V56,A29,X37:X56))/Resumen!$D$1 -> 0 | D29: =C29*Resumen!$D$1 -> 0
A30: Supermercado | B30: =COUNTIF(B37:B56,A30)+COUNTIF(G37:G56,A30)+COUNTIF(L37:L56,A30)+COUNTIF(Q37:Q56,A30)+COUNTIF(V37:V56,A30) -> 0 | C30: =SUMIF(B37:B56,A30,C37:C56)+SUMIF(G37:G56,A30,H37:H56)+SUMIF(L37:L56,A30,M37:M56)+SUMIF(Q37:Q56,A30,R37:R56)+SUMIF(V37:V56,A30,W37:W56)+(SUMIF(B37:B56,A30,D37:D56)+SUMIF(G37:G56,A30,I37:I56)+SUMIF(L37:L56,A30,N37:N56)+SUMIF(Q37:Q56,A30,S37:S56)+SUMIF(V37:V56,A30,X37:X56))/Resumen!$D$1 -> 0 | D30: =C30*Resumen!$D$1 -> 0
A31: Suscripciones | B31: =COUNTIF(B37:B56,A31)+COUNTIF(G37:G56,A31)+COUNTIF(L37:L56,A31)+COUNTIF(Q37:Q56,A31)+COUNTIF(V37:V56,A31) -> 0 | C31: =SUMIF(B37:B56,A31,C37:C56)+SUMIF(G37:G56,A31,H37:H56)+SUMIF(L37:L56,A31,M37:M56)+SUMIF(Q37:Q56,A31,R37:R56)+SUMIF(V37:V56,A31,W37:W56)+(SUMIF(B37:B56,A31,D37:D56)+SUMIF(G37:G56,A31,I37:I56)+SUMIF(L37:L56,A31,N37:N56)+SUMIF(Q37:Q56,A31,S37:S56)+SUMIF(V37:V56,A31,X37:X56))/Resumen!$D$1 -> 0 | D31: =C31*Resumen!$D$1 -> 0
A32: TOTAL MES | B32: =SUM(B13:B31) -> 0 | C32: =SUM(C13:C31) -> 0 | D32: =SUM(D13:D31) -> 0
A34: REGISTRO SEMANAL
A35: SEMANA 1 | F35: SEMANA 2 | K35: SEMANA 3 | P35: SEMANA 4 | U35: SEMANA 5
A36: Concepto | B36: Categ. | C36: AED | D36: EUR | E36: Fecha | F36: Concepto | G36: Categ. | H36: AED | I36: EUR | J36: Fecha | K36: Concepto | L36: Categ. | M36: AED | N36: EUR | O36: Fecha | P36: Concepto | Q36: Categ. | R36: AED | S36: EUR | T36: Fecha | U36: Concepto | V36: Categ. | W36: AED | X36: EUR
A57: TOTAL | C57: =SUM(C37:C56)+SUM(D37:D56)/Resumen!$D$1 -> 0 | D57: =SUM(D37:D56)+SUM(C37:C56)*Resumen!$D$1 -> 0 | H57: =SUM(H37:H56)+SUM(I37:I56)/Resumen!$D$1 -> 0 | I57: =SUM(I37:I56)+SUM(H37:H56)*Resumen!$D$1 -> 0 | M57: =SUM(M37:M56)+SUM(N37:N56)/Resumen!$D$1 -> 0 | N57: =SUM(N37:N56)+SUM(M37:M56)*Resumen!$D$1 -> 0 | R57: =SUM(R37:R56)+SUM(S37:S56)/Resumen!$D$1 -> 0 | S57: =SUM(S37:S56)+SUM(R37:R56)*Resumen!$D$1 -> 0 | W57: =SUM(W37:W56)+SUM(X37:X56)/Resumen!$D$1 -> 0 | X57: =SUM(X37:X56)+SUM(W37:W56)*Resumen!$D$1 -> 0
A58: RESTANTE | C58: =Resumen!$B$32-C57 -> 2980 | D58: =Resumen!$C$32-D57 -> 715.2 | H58: =C58-H57 -> 2980 | I58: =D58-I57 -> 715.2 | M58: =H58-M57 -> 2980 | N58: =I58-N57 -> 715.2 | R58: =M58-R57 -> 2980 | S58: =N58-S57 -> 715.2 | W58: =R58-W57 -> 2980 | X58: =S58-X57 -> 715.2

Sheet Marzo
A1: INGRESOS MENSUALES
A2: Concepto | C2: Total AED | D2: Total EUR
A3: Salario Santi | C3: =Resumen!$C$4 -> 25000 | D3: =C3*Resumen!$D$1 -> 6000
A4: Salario Bea | C4: =D4/Resumen!$D$1 -> 5000 | D4: =Resumen!$C$5*Resumen!$D$1 -> 1200
A5: Ingresos extra | C5: =D5/Resumen!$D$1 -> 1800 | D5: =Resumen!$C$6*Resumen!$D$1 -> 432
A6: TOTAL INGRESOS | C6: =SUM(C3:C5) -> 31800 | D6: =SUM(D3:D5) -> 7632
A7: BALANCE (Ingreso - Gasto) | C7: =C6-C32 -> 31800 | D7: =D6-D32 -> 7632
A9: GASTOS MENSUALES
A11: RESUMEN POR CATEGORÍA
A12: Categoría | B12: Nº Gastos | C12: Total AED | D12: Total EUR
A13: Restaurantes | B13: =COUNTIF(B37:B56,A13)+COUNTIF(G37:G56,A13)+COUNTIF(L37:L56,A13)+COUNTIF(Q37:Q56,A13)+COUNTIF(V37:V56,A13) -> 0 | C13: =SUMIF(B37:B56,A13,C37:C56)+SUMIF(G37:G56,A13,H37:H56)+SUMIF(L37:L56,A13,M37:M56)+SUMIF(Q37:Q56,A13,R37:R56)+SUMIF(V37:V56,A13,W37:W56)+(SUMIF(B37:B56,A13,D37:D56)+SUMIF(G37:G56,A13,I37:I56)+SUMIF(L37:L56,A13,N37:N56)+SUMIF(Q37:Q56,A13,S37:S56)+SUMIF(V37:V56,A13,X37:X56))/Resumen!$D$1 -> 0 | D13: =C13*Resumen!$D$1 -> 0
A14: Ocio | B14: =COUNTIF(B37:B56,A14)+COUNTIF(G37:G56,A14)+COUNTIF(L37:L56,A14)+COUNTIF(Q37:Q56,A14)+COUNTIF(V37:V56,A14) -> 0 | C14: =SUMIF(B37:B56,A14,C37:C56)+SUMIF(G37:G56,A14,H37:H56)+SUMIF(L37:L56,A14,M37:M56)+SUMIF(Q37:Q56,A14,R37:R56)+SUMIF(V37:V56,A14,W37:W56)+(SUMIF(B37:B56,A14,D37:D56)+SUMIF(G37:G56,A14,I37:I56)+SUMIF(L37:L56,A14,N37:N56)+SUMIF(Q37:Q56,A14,S37:S56)+SUMIF(V37:V56,A14,X37:X56))/Resumen!$D$1 -> 0 | D14: =C14*Resumen!$D$1 -> 0
A15: Compras | B15: =COUNTIF(B37:B56,A15)+COUNTIF(G37:G56,A15)+COUNTIF(L37:L56,A15)+COUNTIF(Q37:Q56,A15)+COUNTIF(V37:V56,A15) -> 0 | C15: =SUMIF(B37:B56,A15,C37:C56)+SUMIF(G37:G56,A15,H37:H56)+SUMIF(L37:L56,A15,M37:M56)+SUMIF(Q37:Q56,A15,R37:R56)+SUMIF(V37:V56,A15,W37:W56)+(SUMIF(B37:B56,A15,D37:D56)+SUMIF(G37:G56,A15,I37:I56)+SUMIF(L37:L56,A15,N37:N56)+SUMIF(Q37:Q56,A15,S37:S56)+SUMIF(V37:V56,A15,X37:X56))/Resumen!$D$1 -> 0 | D15: =C15*Resumen!$D$1 -> 0
A16: Salud | B16: =COUNTIF(B37:B56,A16)+COUNTIF(G37:G56,A16)+COUNTIF(L37:L56,A16)+COUNTIF(Q37:Q56,A16)+COUNTIF(V37:V56,A16) -> 0 | C16: =SUMIF(B37:B56,A16,C37:C56)+SUMIF(G37:G56,A16,H37:H56)+SUMIF(L37:L56,A16,M37:M56)+SUMIF(Q37:Q56,A16,R37:R56)+SUMIF(V37:V56,A16,W37:W56)+(SUMIF(B37:B56,A16,D37:D56)+SUMIF(G37:G56,A16,I37:I56)+SUMIF(L37:L56,A16,N37:N56)+SUMIF(Q37:Q56,A16,S37:S56)+SUMIF(V37:V56,A16,X37:X56))/Resumen!$D$1 -> 0 | D16: =C16*Resumen!$D$1 -> 0
A17: Viajes | B17: =COUNTIF(B37:B56,A17)+COUNTIF(G37:G56,A17)+COUNTIF(L37:L56,A17)+COUNTIF(Q37:Q56,A17)+COUNTIF(V37:V56,A17) -> 0 | C17: =SUMIF(B37:B56,A17,C37:C56)+SUMIF(G37:G56,A17,H37:H56)+SUMIF(L37:L56,A17,M37:M56)+SUMIF(Q37:Q56,A17,R37:R56)+SUMIF(V37:V56,A17,W37:W56)+(SUMIF(B37:B56,A17,D37:D56)+SUMIF(G37:G56,A17,I37:I56)+SUMIF(L37:L56,A17,N37:N56)+SUMIF(Q37:Q56,A17,S37:S56)+SUMIF(V37:V56,A17,X37:X56))/Resumen!$D$1 -> 0 | D17: =C17*Resumen!$D$1 -> 0
A18: Santi | B18: =COUNTIF(B37:B56,A18)+COUNTIF(G37:G56,A18)+COUNTIF(L37:L56,A18)+COUNTIF(Q37:Q56,A18)+COUNTIF(V37:V56,A18) -> 0 | C18: =SUMIF(B37:B56,A18,C37:C56)+SUMIF(G37:G56,A18,H37:H56)+SUMIF(L37:L56,A18,M37:M56)+SUMIF(Q37:Q56,A18,R37:R56)+SUMIF(V37:V56,A18,W37:W56)+(SUMIF(B37:B56,A18,D37:D56)+SUMIF(G37:G56,A18,I37:I56)+SUMIF(L37:L56,A18,N37:N56)+SUMIF(Q37:Q56,A18,S37:S56)+SUMIF(V37:V56,A18,X37:X56))/Resumen!$D$1 -> 0 | D18: =C18*Resumen!$D$1 -> 0
A19: Bea | B19: =COUNTIF(B37:B56,A19)+COUNTIF(G37:G56,A19)+COUNTIF(L37:L56,A19)+COUNTIF(Q37:Q56,A19)+COUNTIF(V37:V56,A19) -> 0 | C19: =SUMIF(B37:B56,A19,C37:C56)+SUMIF(G37:G56,A19,H37:H56)+SUMIF(L37:L56,A19,M37:M56)+SUMIF(Q37:Q56,A19,R37:R56)+SUMIF(V37:V56,A19,W37:W56)+(SUMIF(B37:B56,A19,D37:D56)+SUMIF(G37:G56,A19,I37:I56)+SUMIF(L37:L56,A19,N37:N56)+SUMIF(Q37:Q56,A19,S37:S56)+SUMIF(V37:V56,A19,X37:X56))/Resumen!$D$1 -> 0 | D19: =C19*Resumen!$D$1 -> 0
A20: Personal | B20: =COUNTIF(B37:B56,A20)+COUNTIF(G37:G56,A20)+COUNTIF(L37:L56,A20)+COUNTIF(Q37:Q56,A20)+COUNTIF(V37:V56,A20) -> 0 | C20: =SUMIF(B37:B56,A20,C37:C56)+SUMIF(G37:G56,A20,H37:H56)+SUMIF(L37:L56,A20,M37:M56)+SUMIF(Q37:Q56,A20,R37:R56)+SUMIF(V37:V56,A20,W37:W56)+(SUMIF(B37:B56,A20,D37:D56)+SUMIF(G37:G56,A20,I37:I56)+SUMIF(L37:L56,A20,N37:N56)+SUMIF(Q37:Q56,A20,S37:S56)+SUMIF(V37:V56,A20,X37:X56))/Resumen!$D$1 -> 0 | D20: =C20*Resumen!$D$1 -> 0
A21: Transporte | B21: =COUNTIF(B37:B56,A21)+COUNTIF(G37:G56,A21)+COUNTIF(L37:L56,A21)+COUNTIF(Q37:Q56,A21)+COUNTIF(V37:V56,A21) -> 0 | C21: =SUMIF(B37:B56,A21,C37:C56)+SUMIF(G37:G56,A21,H37:H56)+SUMIF(L37:L56,A21,M37:M56)+SUMIF(Q37:Q56,A21,R37:R56)+SUMIF(V37:V56,A21,W37:W56)+(SUMIF(B37:B56,A21,D37:D56)+SUMIF(G37:G56,A21,I37:I56)+SUMIF(L37:L56,A21,N37:N56)+SUMIF(Q37:Q56,A21,S37:S56)+SUMIF(V37:V56,A21,X37:X56))/Resumen!$D$1 -> 0 | D21: =C21*Resumen!$D$1 -> 0
A22: Regalos | B22: =COUNTIF(B37:B56,A22)+COUNTIF(G37:G56,A22)+COUNTIF(L37:L56,A22)+COUNTIF(Q37:Q56,A22)+COUNTIF(V37:V56,A22) -> 0 | C22: =SUMIF(B37:B56,A22,C37:C56)+SUMIF(G37:G56,A22,H37:H56)+SUMIF(L37:L56,A22,M37:M56)+SUMIF(Q37:Q56,A22,R37:R56)+SUMIF(V37:V56,A22,W37:W56)+(SUMIF(B37:B56,A22,D37:D56)+SUMIF(G37:G56,A22,I37:I56)+SUMIF(L37:L56,A22,N37:N56)+SUMIF(Q37:Q56,A22,S37:S56)+SUMIF(V37:V56,A22,X37:X56))/Resumen!$D$1 -> 0 | D22: =C22*Resumen!$D$1 -> 0
A23: Alquiler piso | B23: =COUNTIF(B37:B56,A23)+COUNTIF(G37:G56,A23)+COUNTIF(L37:L56,A23)+COUNTIF(Q37:Q56,A23)+COUNTIF(V37:V56,A23) -> 0 | C23: =SUMIF(B37:B56,A23,C37:C56)+SUMIF(G37:G56,A23,H37:H56)+SUMIF(L37:L56,A23,M37:M56)+SUMIF(Q37:Q56,A23,R37:R56)+SUMIF(V37:V56,A23,W37:W56)+(SUMIF(B37:B56,A23,D37:D56)+SUMIF(G37:G56,A23,I37:I56)+SUMIF(L37:L56,A23,N37:N56)+SUMIF(Q37:Q56,A23,S37:S56)+SUMIF(V37:V56,A23,X37:X56))/Resumen!$D$1 -> 0 | D23: =C23*Resumen!$D$1 -> 0
A24: Mudanza | B24: =COUNTIF(B37:B56,A24)+COUNTIF(G37:G56,A24)+COUNTIF(L37:L56,A24)+COUNTIF(Q37:Q56,A24)+COUNTIF(V37:V56,A24) -> 0 | C24: =SUMIF(B37:B56,A24,C37:C56)+SUMIF(G37:G56,A24,H37:H56)+SUMIF(L37:L56,A24,M37:M56)+SUMIF(Q37:Q56,A24,R37:R56)+SUMIF(V37:V56,A24,W37:W56)+(SUMIF(B37:B56,A24,D37:D56)+SUMIF(G37:G56,A24,I37:I56)+SUMIF(L37:L56,A24,N37:N56)+SUMIF(Q37:Q56,A24,S37:S56)+SUMIF(V37:V56,A24,X37:X56))/Resumen!$D$1 -> 0 | D24: =C24*Resumen!$D$1 -> 0
A25: Tasas | B25: =COUNTIF(B37:B56,A25)+COUNTIF(G37:G56,A25)+COUNTIF(L37:L56,A25)+COUNTIF(Q37:Q56,A25)+COUNTIF(V37:V56,A25) -> 0 | C25: =SUMIF(B37:B56,A25,C37:C56)+SUMIF(G37:G56,A25,H37:H56)+SUMIF(L37:L56,A25,M37:M56)+SUMIF(Q37:Q56,A25,R37:R56)+SUMIF(V37:V56,A25,W37:W56)+(SUMIF(B37:B56,A25,D37:D56)+SUMIF(G37:G56,A25,I37:I56)+SUMIF(L37:L56,A25,N37:N56)+SUMIF(Q37:Q56,A25,S37:S56)+SUMIF(V37:V56,A25,X37:X56))/Resumen!$D$1 -> 0 | D25: =C25*Resumen!$D$1 -> 0
A26: Suministros piso | B26: =COUNTIF(B37:B56,A26)+COUNTIF(G37:G56,A26)+COUNTIF(L37:L56,A26)+COUNTIF(Q37:Q56,A26)+COUNTIF(V37:V56,A26) -> 0 | C26: =SUMIF(B37:B56,A26,C37:C56)+SUMIF(G37:G56,A26,H37:H56)+SUMIF(L37:L56,A26,M37:M56)+SUMIF(Q37:Q56,A26,R37:R56)+SUMIF(V37:V56,A26,W37:W56)+(SUMIF(B37:B56,A26,D37:D56)+SUMIF(G37:G56,A26,I37:I56)+SUMIF(L37:L56,A26,N37:N56)+SUMIF(Q37:Q56,A26,S37:S56)+SUMIF(V37:V56,A26,X37:X56))/Resumen!$D$1 -> 0 | D26: =C26*Resumen!$D$1 -> 0
A27: Otros | B27: =COUNTIF(B37:B56,A27)+COUNTIF(G37:G56,A27)+COUNTIF(L37:L56,A27)+COUNTIF(Q37:Q56,A27)+COUNTIF(V37:V56,A27) -> 0 | C27: =SUMIF(B37:B56,A27,C37:C56)+SUMIF(G37:G56,A27,H37:H56)+SUMIF(L37:L56,A27,M37:M56)+SUMIF(Q37:Q56,A27,R37:R56)+SUMIF(V37:V56,A27,W37:W56)+(SUMIF(B37:B56,A27,D37:D56)+SUMIF(G37:G56,A27,I37:I56)+SUMIF(L37:L56,A27,N37:N56)+SUMIF(Q37:Q56,A27,S37:S56)+SUMIF(V37:V56,A27,X37:X56))/Resumen!$D$1 -> 0 | D27: =C27*Resumen!$D$1 -> 0
A28: Hogar | B28: =COUNTIF(B37:B56,A28)+COUNTIF(G37:G56,A28)+COUNTIF(L37:L56,A28)+COUNTIF(Q37:Q56,A28)+COUNTIF(V37:V56,A28) -> 0 | C28: =SUMIF(B37:B56,A28,C37:C56)+SUMIF(G37:G56,A28,H37:H56)+SUMIF(L37:L56,A28,M37:M56)+SUMIF(Q37:Q56,A28,R37:R56)+SUMIF(V37:V56,A28,W37:W56)+(SUMIF(B37:B56,A28,D37:D56)+SUMIF(G37:G56,A28,I37:I56)+SUMIF(L37:L56,A28,N37:N56)+SUMIF(Q37:Q56,A28,S37:S56)+SUMIF(V37:V56,A28,X37:X56))/Resumen!$D$1 -> 0 | D28: =C28*Resumen!$D$1 -> 0
A29: Delivery | B29: =COUNTIF(B37:B56,A29)+COUNTIF(G37:G56,A29)+COUNTIF(L37:L56,A29)+COUNTIF(Q37:Q56,A29)+COUNTIF(V37:V56,A29) -> 0 | C29: =SUMIF(B37:B56,A29,C37:C56)+SUMIF(G37:G56,A29,H37:H56)+SUMIF(L37:L56,A29,M37:M56)+SUMIF(Q37:Q56,A29,R37:R56)+SUMIF(V37:V56,A29,W37:W56)+(SUMIF(B37:B56,A29,D37:D56)+SUMIF(G37:G56,A29,I37:I56)+SUMIF(L37:L56,A29,N37:N56)+SUMIF(Q37:Q56,A29,S37:S56)+SUMIF(V37:V56,A29,X37:X56))/Resumen!$D$1 -> 0 | D29: =C29*Resumen!$D$1 -> 0
A30: Supermercado | B30: =COUNTIF(B37:B56,A30)+COUNTIF(G37:G56,A30)+COUNTIF(L37:L56,A30)+COUNTIF(Q37:Q56,A30)+COUNTIF(V37:V56,A30) -> 0 | C30: =SUMIF(B37:B56,A30,C37:C56)+SUMIF(G37:G56,A30,H37:H56)+SUMIF(L37:L56,A30,M37:M56)+SUMIF(Q37:Q56,A30,R37:R56)+SUMIF(V37:V56,A30,W37:W56)+(SUMIF(B37:B56,A30,D37:D56)+SUMIF(G37:G56,A30,I37:I56)+SUMIF(L37:L56,A30,N37:N56)+SUMIF(Q37:Q56,A30,S37:S56)+SUMIF(V37:V56,A30,X37:X56))/Resumen!$D$1 -> 0 | D30: =C30*Resumen!$D$1 -> 0
A31: Suscripciones | B31: =COUNTIF(B37:B56,A31)+COUNTIF(G37:G56,A31)+COUNTIF(L37:L56,A31)+COUNTIF(Q37:Q56,A31)+COUNTIF(V37:V56,A31) -> 0 | C31: =SUMIF(B37:B56,A31,C37:C56)+SUMIF(G37:G56,A31,H37:H56)+SUMIF(L37:L56,A31,M37:M56)+SUMIF(Q37:Q56,A31,R37:R56)+SUMIF(V37:V56,A31,W37:W56)+(SUMIF(B37:B56,A31,D37:D56)+SUMIF(G37:G56,A31,I37:I56)+SUMIF(L37:L56,A31,N37:N56)+SUMIF(Q37:Q56,A31,S37:S56)+SUMIF(V37:V56,A31,X37:X56))/Resumen!$D$1 -> 0 | D31: =C31*Resumen!$D$1 -> 0
A32: TOTAL MES | B32: =SUM(B13:B31) -> 0 | C32: =SUM(C13:C31) -> 0 | D32: =SUM(D13:D31) -> 0
A34: REGISTRO SEMANAL
A35: SEMANA 1 | F35: SEMANA 2 | K35: SEMANA 3 | P35: SEMANA 4 | U35: SEMANA 5
A36: Concepto | B36: Categ. | C36: AED | D36: EUR | E36: Fecha | F36: Concepto | G36: Categ. | H36: AED | I36: EUR | J36: Fecha | K36: Concepto | L36: Categ. | M36: AED | N36: EUR | O36: Fecha | P36: Concepto | Q36: Categ. | R36: AED | S36: EUR | T36: Fecha | U36: Concepto | V36: Categ. | W36: AED | X36: EUR
A57: TOTAL | C57: =SUM(C37:C56)+SUM(D37:D56)/Resumen!$D$1 -> 0 | D57: =SUM(D37:D56)+SUM(C37:C56)*Resumen!$D$1 -> 0 | H57: =SUM(H37:H56)+SUM(I37:I56)/Resumen!$D$1 -> 0 | I57: =SUM(I37:I56)+SUM(H37:H56)*Resumen!$D$1 -> 0 | M57: =SUM(M37:M56)+SUM(N37:N56)/Resumen!$D$1 -> 0 | N57: =SUM(N37:N56)+SUM(M37:M56)*Resumen!$D$1 -> 0 | R57: =SUM(R37:R56)+SUM(S37:S56)/Resumen!$D$1 -> 0 | S57: =SUM(S37:S56)+SUM(R37:R56)*Resumen!$D$1 -> 0 | W57: =SUM(W37:W56)+SUM(X37:X56)/Resumen!$D$1 -> 0 | X57: =SUM(X37:X56)+SUM(W37:W56)*Resumen!$D$1 -> 0
A58: RESTANTE | C58: =Resumen!$B$32-C57 -> 2980 | D58: =Resumen!$C$32-D57 -> 715.2 | H58: =C58-H57 -> 2980 | I58: =D58-I57 -> 715.2 | M58: =H58-M57 -> 2980 | N58: =I58-N57 -> 715.2 | R58: =M58-R57 -> 2980 | S58: =N58-S57 -> 715.2 | W58: =R58-W57 -> 2980 | X58: =S58-X57 -> 715.2

Sheet Abril
A1: INGRESOS MENSUALES
A2: Concepto | C2: Total AED | D2: Total EUR
A3: Salario Santi | C3: =Resumen!$C$4 -> 25000 | D3: =C3*Resumen!$D$1 -> 6000
A4: Salario Bea | C4: =D4/Resumen!$D$1 -> 5000 | D4: =Resumen!$C$5*Resumen!$D$1 -> 1200
A5: Ingresos extra | C5: =D5/Resumen!$D$1 -> 1800 | D5: =Resumen!$C$6*Resumen!$D$1 -> 432
A6: TOTAL INGRESOS | C6: =SUM(C3:C5) -> 31800 | D6: =SUM(D3:D5) -> 7632
A7: BALANCE (Ingreso - Gasto) | C7: =C6-C32 -> 8334.8333 | D7: =D6-D32 -> 2000.36
A9: GASTOS MENSUALES
A11: RESUMEN POR CATEGORÍA
A12: Categoría | B12: Nº Gastos | C12: Total AED | D12: Total EUR
A13: Restaurantes | B13: =COUNTIF(B37:B56,A13)+COUNTIF(G37:G56,A13)+COUNTIF(L37:L56,A13)+COUNTIF(Q37:Q56,A13)+COUNTIF(V37:V56,A13) -> 22 | C13: =SUMIF(B37:B56,A13,C37:C56)+SUMIF(G37:G56,A13,H37:H56)+SUMIF(L37:L56,A13,M37:M56)+SUMIF(Q37:Q56,A13,R37:R56)+SUMIF(V37:V56,A13,W37:W56)+(SUMIF(B37:B56,A13,D37:D56)+SUMIF(G37:G56,A13,I37:I56)+SUMIF(L37:L56,A13,N37:N56)+SUMIF(Q37:Q56,A13,S37:S56)+SUMIF(V37:V56,A13,X37:X56))/Resumen!$D$1 -> 3252.625 | D13: =C13*Resumen!$D$1 -> 780.63
A14: Ocio | B14: =COUNTIF(B37:B56,A14)+COUNTIF(G37:G56,A14)+COUNTIF(L37:L56,A14)+COUNTIF(Q37:Q56,A14)+COUNTIF(V37:V56,A14) -> 5 | C14: =SUMIF(B37:B56,A14,C37:C56)+SUMIF(G37:G56,A14,H37:H56)+SUMIF(L37:L56,A14,M37:M56)+SUMIF(Q37:Q56,A14,R37:R56)+SUMIF(V37:V56,A14,W37:W56)+(SUMIF(B37:B56,A14,D37:D56)+SUMIF(G37:G56,A14,I37:I56)+SUMIF(L37:L56,A14,N37:N56)+SUMIF(Q37:Q56,A14,S37:S56)+SUMIF(V37:V56,A14,X37:X56))/Resumen!$D$1 -> 547.04167 | D14: =C14*Resumen!$D$1 -> 131.29
A15: Compras | B15: =COUNTIF(B37:B56,A15)+COUNTIF(G37:G56,A15)+COUNTIF(L37:L56,A15)+COUNTIF(Q37:Q56,A15)+COUNTIF(V37:V56,A15) -> 6 | C15: =SUMIF(B37:B56,A15,C37:C56)+SUMIF(G37:G56,A15,H37:H56)+SUMIF(L37:L56,A15,M37:M56)+SUMIF(Q37:Q56,A15,R37:R56)+SUMIF(V37:V56,A15,W37:W56)+(SUMIF(B37:B56,A15,D37:D56)+SUMIF(G37:G56,A15,I37:I56)+SUMIF(L37:L56,A15,N37:N56)+SUMIF(Q37:Q56,A15,S37:S56)+SUMIF(V37:V56,A15,X37:X56))/Resumen!$D$1 -> 1355.6667 | D15: =C15*Resumen!$D$1 -> 325.36
A16: Salud | B16: =COUNTIF(B37:B56,A16)+COUNTIF(G37:G56,A16)+COUNTIF(L37:L56,A16)+COUNTIF(Q37:Q56,A16)+COUNTIF(V37:V56,A16) -> 3 | C16: =SUMIF(B37:B56,A16,C37:C56)+SUMIF(G37:G56,A16,H37:H56)+SUMIF(L37:L56,A16,M37:M56)+SUMIF(Q37:Q56,A16,R37:R56)+SUMIF(V37:V56,A16,W37:W56)+(SUMIF(B37:B56,A16,D37:D56)+SUMIF(G37:G56,A16,I37:I56)+SUMIF(L37:L56,A16,N37:N56)+SUMIF(Q37:Q56,A16,S37:S56)+SUMIF(V37:V56,A16,X37:X56))/Resumen!$D$1 -> 2096.875 | D16: =C16*Resumen!$D$1 -> 503.25
A17: Viajes | B17: =COUNTIF(B37:B56,A17)+COUNTIF(G37:G56,A17)+COUNTIF(L37:L56,A17)+COUNTIF(Q37:Q56,A17)+COUNTIF(V37:V56,A17) -> 0 | C17: =SUMIF(B37:B56,A17,C37:C56)+SUMIF(G37:G56,A17,H37:H56)+SUMIF(L37:L56,A17,M37:M56)+SUMIF(Q37:Q56,A17,R37:R56)+SUMIF(V37:V56,A17,W37:W56)+(SUMIF(B37:B56,A17,D37:D56)+SUMIF(G37:G56,A17,I37:I56)+SUMIF(L37:L56,A17,N37:N56)+SUMIF(Q37:Q56,A17,S37:S56)+SUMIF(V37:V56,A17,X37:X56))/Resumen!$D$1 -> 0 | D17: =C17*Resumen!$D$1 -> 0
A18: Santi | B18: =COUNTIF(B37:B56,A18)+COUNTIF(G37:G56,A18)+COUNTIF(L37:L56,A18)+COUNTIF(Q37:Q56,A18)+COUNTIF(V37:V56,A18) -> 0 | C18: =SUMIF(B37:B56,A18,C37:C56)+SUMIF(G37:G56,A18,H37:H56)+SUMIF(L37:L56,A18,M37:M56)+SUMIF(Q37:Q56,A18,R37:R56)+SUMIF(V37:V56,A18,W37:W56)+(SUMIF(B37:B56,A18,D37:D56)+SUMIF(G37:G56,A18,I37:I56)+SUMIF(L37:L56,A18,N37:N56)+SUMIF(Q37:Q56,A18,S37:S56)+SUMIF(V37:V56,A18,X37:X56))/Resumen!$D$1 -> 0 | D18: =C18*Resumen!$D$1 -> 0
A19: Bea | B19: =COUNTIF(B37:B56,A19)+COUNTIF(G37:G56,A19)+COUNTIF(L37:L56,A19)+COUNTIF(Q37:Q56,A19)+COUNTIF(V37:V56,A19) -> 1 | C19: =SUMIF(B37:B56,A19,C37:C56)+SUMIF(G37:G56,A19,H37:H56)+SUMIF(L37:L56,A19,M37:M56)+SUMIF(Q37:Q56,A19,R37:R56)+SUMIF(V37:V56,A19,W37:W56)+(SUMIF(B37:B56,A19,D37:D56)+SUMIF(G37:G56,A19,I37:I56)+SUMIF(L37:L56,A19,N37:N56)+SUMIF(Q37:Q56,A19,S37:S56)+SUMIF(V37:V56,A19,X37:X56))/Resumen!$D$1 -> 2272.3333 | D19: =C19*Resumen!$D$1 -> 545.36
A20: Personal | B20: =COUNTIF(B37:B56,A20)+COUNTIF(G37:G56,A20)+COUNTIF(L37:L56,A20)+COUNTIF(Q37:Q56,A20)+COUNTIF(V37:V56,A20) -> 0 | C20: =SUMIF(B37:B56,A20,C37:C56)+SUMIF(G37:G56,A20,H37:H56)+SUMIF(L37:L56,A20,M37:M56)+SUMIF(Q37:Q56,A20,R37:R56)+SUMIF(V37:V56,A20,W37:W56)+(SUMIF(B37:B56,A20,D37:D56)+SUMIF(G37:G56,A20,I37:I56)+SUMIF(L37:L56,A20,N37:N56)+SUMIF(Q37:Q56,A20,S37:S56)+SUMIF(V37:V56,A20,X37:X56))/Resumen!$D$1 -> 0 | D20: =C20*Resumen!$D$1 -> 0
A21: Transporte | B21: =COUNTIF(B37:B56,A21)+COUNTIF(G37:G56,A21)+COUNTIF(L37:L56,A21)+COUNTIF(Q37:Q56,A21)+COUNTIF(V37:V56,A21) -> 7 | C21: =SUMIF(B37:B56,A21,C37:C56)+SUMIF(G37:G56,A21,H37:H56)+SUMIF(L37:L56,A21,M37:M56)+SUMIF(Q37:Q56,A21,R37:R56)+SUMIF(V37:V56,A21,W37:W56)+(SUMIF(B37:B56,A21,D37:D56)+SUMIF(G37:G56,A21,I37:I56)+SUMIF(L37:L56,A21,N37:N56)+SUMIF(Q37:Q56,A21,S37:S56)+SUMIF(V37:V56,A21,X37:X56))/Resumen!$D$1 -> 4430.7083 | D21: =C21*Resumen!$D$1 -> 1063.37
A22: Regalos | B22: =COUNTIF(B37:B56,A22)+COUNTIF(G37:G56,A22)+COUNTIF(L37:L56,A22)+COUNTIF(Q37:Q56,A22)+COUNTIF(V37:V56,A22) -> 0 | C22: =SUMIF(B37:B56,A22,C37:C56)+SUMIF(G37:G56,A22,H37:H56)+SUMIF(L37:L56,A22,M37:M56)+SUMIF(Q37:Q56,A22,R37:R56)+SUMIF(V37:V56,A22,W37:W56)+(SUMIF(B37:B56,A22,D37:D56)+SUMIF(G37:G56,A22,I37:I56)+SUMIF(L37:L56,A22,N37:N56)+SUMIF(Q37:Q56,A22,S37:S56)+SUMIF(V37:V56,A22,X37:X56))/Resumen!$D$1 -> 0 | D22: =C22*Resumen!$D$1 -> 0
A23: Alquiler piso | B23: =COUNTIF(B37:B56,A23)+COUNTIF(G37:G56,A23)+COUNTIF(L37:L56,A23)+COUNTIF(Q37:Q56,A23)+COUNTIF(V37:V56,A23) -> 0 | C23: =SUMIF(B37:B56,A23,C37:C56)+SUMIF(G37:G56,A23,H37:H56)+SUMIF(L37:L56,A23,M37:M56)+SUMIF(Q37:Q56,A23,R37:R56)+SUMIF(V37:V56,A23,W37:W56)+(SUMIF(B37:B56,A23,D37:D56)+SUMIF(G37:G56,A23,I37:I56)+SUMIF(L37:L56,A23,N37:N56)+SUMIF(Q37:Q56,A23,S37:S56)+SUMIF(V37:V56,A23,X37:X56))/Resumen!$D$1 -> 0 | D23: =C23*Resumen!$D$1 -> 0
A24: Mudanza | B24: =COUNTIF(B37:B56,A24)+COUNTIF(G37:G56,A24)+COUNTIF(L37:L56,A24)+COUNTIF(Q37:Q56,A24)+COUNTIF(V37:V56,A24) -> 0 | C24: =SUMIF(B37:B56,A24,C37:C56)+SUMIF(G37:G56,A24,H37:H56)+SUMIF(L37:L56,A24,M37:M56)+SUMIF(Q37:Q56,A24,R37:R56)+SUMIF(V37:V56,A24,W37:W56)+(SUMIF(B37:B56,A24,D37:D56)+SUMIF(G37:G56,A24,I37:I56)+SUMIF(L37:L56,A24,N37:N56)+SUMIF(Q37:Q56,A24,S37:S56)+SUMIF(V37:V56,A24,X37:X56))/Resumen!$D$1 -> 0 | D24: =C24*Resumen!$D$1 -> 0
A25: Tasas | B25: =COUNTIF(B37:B56,A25)+COUNTIF(G37:G56,A25)+COUNTIF(L37:L56,A25)+COUNTIF(Q37:Q56,A25)+COUNTIF(V37:V56,A25) -> 0 | C25: =SUMIF(B37:B56,A25,C37:C56)+SUMIF(G37:G56,A25,H37:H56)+SUMIF(L37:L56,A25,M37:M56)+SUMIF(Q37:Q56,A25,R37:R56)+SUMIF(V37:V56,A25,W37:W56)+(SUMIF(B37:B56,A25,D37:D56)+SUMIF(G37:G56,A25,I37:I56)+SUMIF(L37:L56,A25,N37:N56)+SUMIF(Q37:Q56,A25,S37:S56)+SUMIF(V37:V56,A25,X37:X56))/Resumen!$D$1 -> 0 | D25: =C25*Resumen!$D$1 -> 0
A26: Suministros piso | B26: =COUNTIF(B37:B56,A26)+COUNTIF(G37:G56,A26)+COUNTIF(L37:L56,A26)+COUNTIF(Q37:Q56,A26)+COUNTIF(V37:V56,A26) -> 0 | C26: =SUMIF(B37:B56,A26,C37:C56)+SUMIF(G37:G56,A26,H37:H56)+SUMIF(L37:L56,A26,M37:M56)+SUMIF(Q37:Q56,A26,R37:R56)+SUMIF(V37:V56,A26,W37:W56)+(SUMIF(B37:B56,A26,D37:D56)+SUMIF(G37:G56,A26,I37:I56)+SUMIF(L37:L56,A26,N37:N56)+SUMIF(Q37:Q56,A26,S37:S56)+SUMIF(V37:V56,A26,X37:X56))/Resumen!$D$1 -> 0 | D26: =C26*Resumen!$D$1 -> 0
A27: Otros | B27: =COUNTIF(B37:B56,A27)+COUNTIF(G37:G56,A27)+COUNTIF(L37:L56,A27)+COUNTIF(Q37:Q56,A27)+COUNTIF(V37:V56,A27) -> 7 | C27: =SUMIF(B37:B56,A27,C37:C56)+SUMIF(G37:G56,A27,H37:H56)+SUMIF(L37:L56,A27,M37:M56)+SUMIF(Q37:Q56,A27,R37:R56)+SUMIF(V37:V56,A27,W37:W56)+(SUMIF(B37:B56,A27,D37:D56)+SUMIF(G37:G56,A27,I37:I56)+SUMIF(L37:L56,A27,N37:N56)+SUMIF(Q37:Q56,A27,S37:S56)+SUMIF(V37:V56,A27,X37:X56))/Resumen!$D$1 -> 939.5 | D27: =C27*Resumen!$D$1 -> 225.48
A28: Hogar | B28: =COUNTIF(B37:B56,A28)+COUNTIF(G37:G56,A28)+COUNTIF(L37:L56,A28)+COUNTIF(Q37:Q56,A28)+COUNTIF(V37:V56,A28) -> 1 | C28: =SUMIF(B37:B56,A28,C37:C56)+SUMIF(G37:G56,A28,H37:H56)+SUMIF(L37:L56,A28,M37:M56)+SUMIF(Q37:Q56,A28,R37:R56)+SUMIF(V37:V56,A28,W37:W56)+(SUMIF(B37:B56,A28,D37:D56)+SUMIF(G37:G56,A28,I37:I56)+SUMIF(L37:L56,A28,N37:N56)+SUMIF(Q37:Q56,A28,S37:S56)+SUMIF(V37:V56,A28,X37:X56))/Resumen!$D$1 -> 6614.8333 | D28: =C28*Resumen!$D$1 -> 1587.56
A29: Delivery | B29: =COUNTIF(B37:B56,A29)+COUNTIF(G37:G56,A29)+COUNTIF(L37:L56,A29)+COUNTIF(Q37:Q56,A29)+COUNTIF(V37:V56,A29) -> 10 | C29: =SUMIF(B37:B56,A29,C37:C56)+SUMIF(G37:G56,A29,H37:H56)+SUMIF(L37:L56,A29,M37:M56)+SUMIF(Q37:Q56,A29,R37:R56)+SUMIF(V37:V56,A29,W37:W56)+(SUMIF(B37:B56,A29,D37:D56)+SUMIF(G37:G56,A29,I37:I56)+SUMIF(L37:L56,A29,N37:N56)+SUMIF(Q37:Q56,A29,S37:S56)+SUMIF(V37:V56,A29,X37:X56))/Resumen!$D$1 -> 849.08333 | D29: =C29*Resumen!$D$1 -> 203.78
A30: Supermercado | B30: =COUNTIF(B37:B56,A30)+COUNTIF(G37:G56,A30)+COUNTIF(L37:L56,A30)+COUNTIF(Q37:Q56,A30)+COUNTIF(V37:V56,A30) -> 9 | C30: =SUMIF(B37:B56,A30,C37:C56)+SUMIF(G37:G56,A30,H37:H56)+SUMIF(L37:L56,A30,M37:M56)+SUMIF(Q37:Q56,A30,R37:R56)+SUMIF(V37:V56,A30,W37:W56)+(SUMIF(B37:B56,A30,D37:D56)+SUMIF(G37:G56,A30,I37:I56)+SUMIF(L37:L56,A30,N37:N56)+SUMIF(Q37:Q56,A30,S37:S56)+SUMIF(V37:V56,A30,X37:X56))/Resumen!$D$1 -> 639.875 | D30: =C30*Resumen!$D$1 -> 153.57
A31: Suscripciones | B31: =COUNTIF(B37:B56,A31)+COUNTIF(G37:G56,A31)+COUNTIF(L37:L56,A31)+COUNTIF(Q37:Q56,A31)+COUNTIF(V37:V56,A31) -> 2 | C31: =SUMIF(B37:B56,A31,C37:C56)+SUMIF(G37:G56,A31,H37:H56)+SUMIF(L37:L56,A31,M37:M56)+SUMIF(Q37:Q56,A31,R37:R56)+SUMIF(V37:V56,A31,W37:W56)+(SUMIF(B37:B56,A31,D37:D56)+SUMIF(G37:G56,A31,I37:I56)+SUMIF(L37:L56,A31,N37:N56)+SUMIF(Q37:Q56,A31,S37:S56)+SUMIF(V37:V56,A31,X37:X56))/Resumen!$D$1 -> 466.625 | D31: =C31*Resumen!$D$1 -> 111.99
A32: TOTAL MES | B32: =SUM(B13:B31) -> 73 | C32: =SUM(C13:C31) -> 23465.167 | D32: =SUM(D13:D31) -> 5631.64
A34: REGISTRO SEMANAL
A35: SEMANA 1 | F35: SEMANA 2 | K35: SEMANA 3 | P35: SEMANA 4 | U35: SEMANA 5
A36: Concepto | B36: Categ. | C36: AED | D36: EUR | E36: Fecha | F36: Concepto | G36: Categ. | H36: AED | I36: EUR | J36: Fecha | K36: Concepto | L36: Categ. | M36: AED | N36: EUR | O36: Fecha | P36: Concepto | Q36: Categ. | R36: AED | S36: EUR | T36: Fecha | U36: Concepto | V36: Categ. | W36: AED | X36: EUR
A37: Starbucks | B37: Restaurantes | D37: 7.55 | F37: Careem | G37: Delivery | I37: 18.7 | K37: Emarat 6565 | L37: Otros | N37: 36.1 | P37: Lime | Q37: Transporte | S37: 16.04 | U37: UAE Tenis fed | V37: Ocio | W37: 15
A38: Zara | B38: Compras | D38: 57.33 | F38: Careem | G38: Delivery | I38: 16.72 | K38: Sobremesa | L38: Restaurantes | N38: 100.5 | P38: Careem | Q38: Delivery | S38: 34.15 | U38: UAE Tenis fed | V38: Ocio | W38: 262.5
A39: Shabab Stores | B39: Compras | D39: 44.26 | F39: Hubba caffee | G39: Restaurantes | I39: 3.19 | K39: 12 carts rest | L39: Restaurantes | N39: 8.42 | P39: Noq zajel courier | Q39: Delivery | S39: 24.55 | U39: Salik optical | V39: Otros
A40: New Shangai | B40: Restaurantes | D40: 36.1 | F40: Hexa café | G40: Restaurantes | I40: 5.94 | K40: Arabian tea house | L40: Restaurantes | N40: 110.42 | P40: Careem | Q40: Delivery | S40: 12.71 | U40: fertiitas | V40: Salud | X40: 151.25
A41: Booking apartment | B41: Hogar | D41: 1587.56 | F41: Boulevard plaza bsc | G41: Restaurantes | I41: 11.81 | K41: Claude Subscription | L41: Suscripciones | N41: 90 | P41: Lime | Q41: Transporte | S41: 17.34 | U41: du jumbo | V41: Bea | X41: 545.36
A42: Asemas | B42: Otros | D42: 74.52 | F42: Careem | G42: Delivery | I42: 15.89 | K42: Google gemini | L42: Suscripciones | N42: 21.99 | P42: Tim Hortons | Q42: Restaurantes | S42: 8.4
A43: Boulevard plaza bsc | B43: Restaurantes | D43: 11.81 | F43: Generali España | G43: Otros | I43: 54.67 | K43: Far east seafood | L43: Restaurantes | N43: 56.77 | P43: Lime | Q43: Transporte | S43: 10.55
...

Sheet Mayo
A1: INGRESOS MENSUALES
A2: Concepto | C2: Total AED | D2: Total EUR
A3: Salario Santi | C3: =Resumen!$C$4 -> 25000 | D3: =C3*Resumen!$D$1 -> 6000
A4: Salario Bea | C4: =D4/Resumen!$D$1 -> 5000 | D4: =Resumen!$C$5*Resumen!$D$1 -> 1200
A5: Ingresos extra | C5: =D5/Resumen!$D$1 -> 1800 | D5: =Resumen!$C$6*Resumen!$D$1 -> 432
A6: TOTAL INGRESOS | C6: =SUM(C3:C5) -> 31800 | D6: =SUM(D3:D5) -> 7632
A7: BALANCE (Ingreso - Gasto) | C7: =C6-C32 -> -46571.572 | D7: =D6-D32 -> -11177.177
A9: GASTOS MENSUALES
A11: RESUMEN POR CATEGORÍA
A12: Categoría | B12: Nº Gastos | C12: Total AED | D12: Total EUR
A13: Restaurantes | B13: =COUNTIF(B37:B86,A13)+COUNTIF(G37:G86,A13)+COUNTIF(L37:L86,A13)+COUNTIF(Q37:Q86,A13)+COUNTIF(V37:V86,A13) -> 17 | C13: =SUMIF(B37:B86,A13,C37:C86)+SUMIF(G37:G86,A13,H37:H86)+SUMIF(L37:L86,A13,M37:M86)+SUMIF(Q37:Q86,A13,R37:R86)+SUMIF(V37:V86,A13,W37:W86)+(SUMIF(B37:B86,A13,D37:D86)+SUMIF(G37:G86,A13,I37:I86)+SUMIF(L37:L86,A13,N37:N86)+SUMIF(Q37:Q86,A13,S37:S86)+SUMIF(V37:V86,A13,X37:X86))/Resumen!$D$1 -> 3310.2083 | D13: =C13*Resumen!$D$1 -> 794.45
A14: Ocio | B14: =COUNTIF(B37:B86,A14)+COUNTIF(G37:G86,A14)+COUNTIF(L37:L86,A14)+COUNTIF(Q37:Q86,A14)+COUNTIF(V37:V86,A14) -> 1 | C14: =SUMIF(B37:B86,A14,C37:C86)+SUMIF(G37:G86,A14,H37:H86)+SUMIF(L37:L86,A14,M37:M86)+SUMIF(Q37:Q86,A14,R37:R86)+SUMIF(V37:V86,A14,W37:W86)+(SUMIF(B37:B86,A14,D37:D86)+SUMIF(G37:G86,A14,I37:I86)+SUMIF(L37:L86,A14,N37:N86)+SUMIF(Q37:Q86,A14,S37:S86)+SUMIF(V37:V86,A14,X37:X86))/Resumen!$D$1 -> 400 | D14: =C14*Resumen!$D$1 -> 96
A15: Compras | B15: =COUNTIF(B37:B86,A15)+COUNTIF(G37:G86,A15)+COUNTIF(L37:L86,A15)+COUNTIF(Q37:Q86,A15)+COUNTIF(V37:V86,A15) -> 5 | C15: =SUMIF(B37:B86,A15,C37:C86)+SUMIF(G37:G86,A15,H37:H86)+SUMIF(L37:L86,A15,M37:M86)+SUMIF(Q37:Q86,A15,R37:R86)+SUMIF(V37:V86,A15,W37:W86)+(SUMIF(B37:B86,A15,D37:D86)+SUMIF(G37:G86,A15,I37:I86)+SUMIF(L37:L86,A15,N37:N86)+SUMIF(Q37:Q86,A15,S37:S86)+SUMIF(V37:V86,A15,X37:X86))/Resumen!$D$1 -> 882.44833 | D15: =C15*Resumen!$D$1 -> 211.7876
A16: Salud | B16: =COUNTIF(B37:B86,A16)+COUNTIF(G37:G86,A16)+COUNTIF(L37:L86,A16)+COUNTIF(Q37:Q86,A16)+COUNTIF(V37:V86,A16) -> 0 | C16: =SUMIF(B37:B86,A16,C37:C86)+SUMIF(G37:G86,A16,H37:H86)+SUMIF(L37:L86,A16,M37:M86)+SUMIF(Q37:Q86,A16,R37:R86)+SUMIF(V37:V86,A16,W37:W86)+(SUMIF(B37:B86,A16,D37:D86)+SUMIF(G37:G86,A16,I37:I86)+SUMIF(L37:L86,A16,N37:N86)+SUMIF(Q37:Q86,A16,S37:S86)+SUMIF(V37:V86,A16,X37:X86))/Resumen!$D$1 -> 0 | D16: =C16*Resumen!$D$1 -> 0
A17: Viajes | B17: =COUNTIF(B37:B86,A17)+COUNTIF(G37:G86,A17)+COUNTIF(L37:L86,A17)+COUNTIF(Q37:Q86,A17)+COUNTIF(V37:V86,A17) -> 0 | C17: =SUMIF(B37:B86,A17,C37:C86)+SUMIF(G37:G86,A17,H37:H86)+SUMIF(L37:L86,A17,M37:M86)+SUMIF(Q37:Q86,A17,R37:R86)+SUMIF(V37:V86,A17,W37:W86)+(SUMIF(B37:B86,A17,D37:D86)+SUMIF(G37:G86,A17,I37:I86)+SUMIF(L37:L86,A17,N37:N86)+SUMIF(Q37:Q86,A17,S37:S86)+SUMIF(V37:V86,A17,X37:X86))/Resumen!$D$1 -> 0 | D17: =C17*Resumen!$D$1 -> 0
A18: Santi | B18: =COUNTIF(B37:B86,A18)+COUNTIF(G37:G86,A18)+COUNTIF(L37:L86,A18)+COUNTIF(Q37:Q86,A18)+COUNTIF(V37:V86,A18) -> 2 | C18: =SUMIF(B37:B86,A18,C37:C86)+SUMIF(G37:G86,A18,H37:H86)+SUMIF(L37:L86,A18,M37:M86)+SUMIF(Q37:Q86,A18,R37:R86)+SUMIF(V37:V86,A18,W37:W86)+(SUMIF(B37:B86,A18,D37:D86)+SUMIF(G37:G86,A18,I37:I86)+SUMIF(L37:L86,A18,N37:N86)+SUMIF(Q37:Q86,A18,S37:S86)+SUMIF(V37:V86,A18,X37:X86))/Resumen!$D$1 -> 1096.7083 | D18: =C18*Resumen!$D$1 -> 263.21
A19: Bea | B19: =COUNTIF(B37:B86,A19)+COUNTIF(G37:G86,A19)+COUNTIF(L37:L86,A19)+COUNTIF(Q37:Q86,A19)+COUNTIF(V37:V86,A19) -> 4 | C19: =SUMIF(B37:B86,A19,C37:C86)+SUMIF(G37:G86,A19,H37:H86)+SUMIF(L37:L86,A19,M37:M86)+SUMIF(Q37:Q86,A19,R37:R86)+SUMIF(V37:V86,A19,W37:W86)+(SUMIF(B37:B86,A19,D37:D86)+SUMIF(G37:G86,A19,I37:I86)+SUMIF(L37:L86,A19,N37:N86)+SUMIF(Q37:Q86,A19,S37:S86)+SUMIF(V37:V86,A19,X37:X86))/Resumen!$D$1 -> 1537.0417 | D19: =C19*Resumen!$D$1 -> 368.89
A20: Personal | B20: =COUNTIF(B37:B86,A20)+COUNTIF(G37:G86,A20)+COUNTIF(L37:L86,A20)+COUNTIF(Q37:Q86,A20)+COUNTIF(V37:V86,A20) -> 0 | C20: =SUMIF(B37:B86,A20,C37:C86)+SUMIF(G37:G86,A20,H37:H86)+SUMIF(L37:L86,A20,M37:M86)+SUMIF(Q37:Q86,A20,R37:R86)+SUMIF(V37:V86,A20,W37:W86)+(SUMIF(B37:B86,A20,D37:D86)+SUMIF(G37:G86,A20,I37:I86)+SUMIF(L37:L86,A20,N37:N86)+SUMIF(Q37:Q86,A20,S37:S86)+SUMIF(V37:V86,A20,X37:X86))/Resumen!$D$1 -> 0 | D20: =C20*Resumen!$D$1 -> 0
A21: Transporte | B21: =COUNTIF(B37:B86,A21)+COUNTIF(G37:G86,A21)+COUNTIF(L37:L86,A21)+COUNTIF(Q37:Q86,A21)+COUNTIF(V37:V86,A21) -> 10 | C21: =SUMIF(B37:B86,A21,C37:C86)+SUMIF(G37:G86,A21,H37:H86)+SUMIF(L37:L86,A21,M37:M86)+SUMIF(Q37:Q86,A21,R37:R86)+SUMIF(V37:V86,A21,W37:W86)+(SUMIF(B37:B86,A21,D37:D86)+SUMIF(G37:G86,A21,I37:I86)+SUMIF(L37:L86,A21,N37:N86)+SUMIF(Q37:Q86,A21,S37:S86)+SUMIF(V37:V86,A21,X37:X86))/Resumen!$D$1 -> 2322.4333 | D21: =C21*Resumen!$D$1 -> 557.384
A22: Regalos | B22: =COUNTIF(B37:B86,A22)+COUNTIF(G37:G86,A22)+COUNTIF(L37:L86,A22)+COUNTIF(Q37:Q86,A22)+COUNTIF(V37:V86,A22) -> 1 | C22: =SUMIF(B37:B86,A22,C37:C86)+SUMIF(G37:G86,A22,H37:H86)+SUMIF(L37:L86,A22,M37:M86)+SUMIF(Q37:Q86,A22,R37:R86)+SUMIF(V37:V86,A22,W37:W86)+(SUMIF(B37:B86,A22,D37:D86)+SUMIF(G37:G86,A22,I37:I86)+SUMIF(L37:L86,A22,N37:N86)+SUMIF(Q37:Q86,A22,S37:S86)+SUMIF(V37:V86,A22,X37:X86))/Resumen!$D$1 -> 1250 | D22: =C22*Resumen!$D$1 -> 300
A23: Alquiler piso | B23: =COUNTIF(B37:B86,A23)+COUNTIF(G37:G86,A23)+COUNTIF(L37:L86,A23)+COUNTIF(Q37:Q86,A23)+COUNTIF(V37:V86,A23) -> 6 | C23: =SUMIF(B37:B86,A23,C37:C86)+SUMIF(G37:G86,A23,H37:H86)+SUMIF(L37:L86,A23,M37:M86)+SUMIF(Q37:Q86,A23,R37:R86)+SUMIF(V37:V86,A23,W37:W86)+(SUMIF(B37:B86,A23,D37:D86)+SUMIF(G37:G86,A23,I37:I86)+SUMIF(L37:L86,A23,N37:N86)+SUMIF(Q37:Q86,A23,S37:S86)+SUMIF(V37:V86,A23,X37:X86))/Resumen!$D$1 -> 34752.542 | D23: =C23*Resumen!$D$1 -> 8340.61
A24: Mudanza | B24: =COUNTIF(B37:B86,A24)+COUNTIF(G37:G86,A24)+COUNTIF(L37:L86,A24)+COUNTIF(Q37:Q86,A24)+COUNTIF(V37:V86,A24) -> 19 | C24: =SUMIF(B37:B86,A24,C37:C86)+SUMIF(G37:G86,A24,H37:H86)+SUMIF(L37:L86,A24,M37:M86)+SUMIF(Q37:Q86,A24,R37:R86)+SUMIF(V37:V86,A24,W37:W86)+(SUMIF(B37:B86,A24,D37:D86)+SUMIF(G37:G86,A24,I37:I86)+SUMIF(L37:L86,A24,N37:N86)+SUMIF(Q37:Q86,A24,S37:S86)+SUMIF(V37:V86,A24,X37:X86))/Resumen!$D$1 -> 26162.615 | D24: =C24*Resumen!$D$1 -> 6279.0276
A25: Tasas | B25: =COUNTIF(B37:B86,A25)+COUNTIF(G37:G86,A25)+COUNTIF(L37:L86,A25)+COUNTIF(Q37:Q86,A25)+COUNTIF(V37:V86,A25) -> 5 | C25: =SUMIF(B37:B86,A25,C37:C86)+SUMIF(G37:G86,A25,H37:H86)+SUMIF(L37:L86,A25,M37:M86)+SUMIF(Q37:Q86,A25,R37:R86)+SUMIF(V37:V86,A25,W37:W86)+(SUMIF(B37:B86,A25,D37:D86)+SUMIF(G37:G86,A25,I37:I86)+SUMIF(L37:L86,A25,N37:N86)+SUMIF(Q37:Q86,A25,S37:S86)+SUMIF(V37:V86,A25,X37:X86))/Resumen!$D$1 -> 2053.97 | D25: =C25*Resumen!$D$1 -> 492.9528
A26: Suministros piso | B26: =COUNTIF(B37:B86,A26)+COUNTIF(G37:G86,A26)+COUNTIF(L37:L86,A26)+COUNTIF(Q37:Q86,A26)+COUNTIF(V37:V86,A26) -> 2 | C26: =SUMIF(B37:B86,A26,C37:C86)+SUMIF(G37:G86,A26,H37:H86)+SUMIF(L37:L86,A26,M37:M86)+SUMIF(Q37:Q86,A26,R37:R86)+SUMIF(V37:V86,A26,W37:W86)+(SUMIF(B37:B86,A26,D37:D86)+SUMIF(G37:G86,A26,I37:I86)+SUMIF(L37:L86,A26,N37:N86)+SUMIF(Q37:Q86,A26,S37:S86)+SUMIF(V37:V86,A26,X37:X86))/Resumen!$D$1 -> 207.125 | D26: =C26*Resumen!$D$1 -> 49.71
A27: Otros | B27: =COUNTIF(B37:B86,A27)+COUNTIF(G37:G86,A27)+COUNTIF(L37:L86,A27)+COUNTIF(Q37:Q86,A27)+COUNTIF(V37:V86,A27) -> 1 | C27: =SUMIF(B37:B86,A27,C37:C86)+SUMIF(G37:G86,A27,H37:H86)+SUMIF(L37:L86,A27,M37:M86)+SUMIF(Q37:Q86,A27,R37:R86)+SUMIF(V37:V86,A27,W37:W86)+(SUMIF(B37:B86,A27,D37:D86)+SUMIF(G37:G86,A27,I37:I86)+SUMIF(L37:L86,A27,N37:N86)+SUMIF(Q37:Q86,A27,S37:S86)+SUMIF(V37:V86,A27,X37:X86))/Resumen!$D$1 -> 1000 | D27: =C27*Resumen!$D$1 -> 240
A28: Hogar | B28: =COUNTIF(B37:B86,A28)+COUNTIF(G37:G86,A28)+COUNTIF(L37:L86,A28)+COUNTIF(Q37:Q86,A28)+COUNTIF(V37:V86,A28) -> 0 | C28: =SUMIF(B37:B86,A28,C37:C86)+SUMIF(G37:G86,A28,H37:H86)+SUMIF(L37:L86,A28,M37:M86)+SUMIF(Q37:Q86,A28,R37:R86)+SUMIF(V37:V86,A28,W37:W86)+(SUMIF(B37:B86,A28,D37:D86)+SUMIF(G37:G86,A28,I37:I86)+SUMIF(L37:L86,A28,N37:N86)+SUMIF(Q37:Q86,A28,S37:S86)+SUMIF(V37:V86,A28,X37:X86))/Resumen!$D$1 -> 0 | D28: =C28*Resumen!$D$1 -> 0
A29: Delivery | B29: =COUNTIF(B37:B86,A29)+COUNTIF(G37:G86,A29)+COUNTIF(L37:L86,A29)+COUNTIF(Q37:Q86,A29)+COUNTIF(V37:V86,A29) -> 19 | C29: =SUMIF(B37:B86,A29,C37:C86)+SUMIF(G37:G86,A29,H37:H86)+SUMIF(L37:L86,A29,M37:M86)+SUMIF(Q37:Q86,A29,R37:R86)+SUMIF(V37:V86,A29,W37:W86)+(SUMIF(B37:B86,A29,D37:D86)+SUMIF(G37:G86,A29,I37:I86)+SUMIF(L37:L86,A29,N37:N86)+SUMIF(Q37:Q86,A29,S37:S86)+SUMIF(V37:V86,A29,X37:X86))/Resumen!$D$1 -> 3360.13 | D29: =C29*Resumen!$D$1 -> 806.4312
A30: Supermercado | B30: =COUNTIF(B37:B86,A30)+COUNTIF(G37:G86,A30)+COUNTIF(L37:L86,A30)+COUNTIF(Q37:Q86,A30)+COUNTIF(V37:V86,A30) -> 2 | C30: =SUMIF(B37:B86,A30,C37:C86)+SUMIF(G37:G86,A30,H37:H86)+SUMIF(L37:L86,A30,M37:M86)+SUMIF(Q37:Q86,A30,R37:R86)+SUMIF(V37:V86,A30,W37:W86)+(SUMIF(B37:B86,A30,D37:D86)+SUMIF(G37:G86,A30,I37:I86)+SUMIF(L37:L86,A30,N37:N86)+SUMIF(Q37:Q86,A30,S37:S86)+SUMIF(V37:V86,A30,X37:X86))/Resumen!$D$1 -> 36.35 | D30: =C30*Resumen!$D$1 -> 8.724
A31: Suscripciones | B31: =COUNTIF(B37:B86,A31)+COUNTIF(G37:G86,A31)+COUNTIF(L37:L86,A31)+COUNTIF(Q37:Q86,A31)+COUNTIF(V37:V86,A31) -> 0 | C31: =SUMIF(B37:B86,A31,C37:C86)+SUMIF(G37:G86,A31,H37:H86)+SUMIF(L37:L86,A31,M37:M86)+SUMIF(Q37:Q86,A31,R37:R86)+SUMIF(V37:V86,A31,W37:W86)+(SUMIF(B37:B86,A31,D37:D86)+SUMIF(G37:G86,A31,I37:I86)+SUMIF(L37:L86,A31,N37:N86)+SUMIF(Q37:Q86,A31,S37:S86)+SUMIF(V37:V86,A31,X37:X86))/Resumen!$D$1 -> 0 | D31: =C31*Resumen!$D$1 -> 0
A32: TOTAL MES | B32: =SUM(B13:B31) -> 94 | C32: =SUM(C13:C31) -> 78371.572 | D32: =SUM(D13:D31) -> 18809.177
A34: REGISTRO SEMANAL
A35: SEMANA 1 | F35: SEMANA 2 | K35: SEMANA 3 | P35: SEMANA 4 | U35: SEMANA 5
A36: Concepto | B36: Categ. | C36: AED | D36: EUR | E36: Fecha | F36: Concepto | G36: Categ. | H36: AED | I36: EUR | J36: Fecha | K36: Concepto | L36: Categ. | M36: AED | N36: EUR | O36: Fecha | P36: Concepto | Q36: Categ. | R36: AED | S36: EUR | T36: Fecha | U36: Concepto | V36: Categ. | W36: AED | X36: EUR
A37: sofa y mesa café | B37: Mudanza | D37: 821.61 | F37: Atmosphere | G37: Restaurantes | I37: 156.92 | K37: Vestido boda Philippa | L37: Bea | N37: 220.9 | O37: 46158
A38: utensilios cocina | B38: Mudanza | D38: 258.15 | F38: Ikea | G38: Mudanza | I38: 258.15 | K38: Comidas varias | L38: Restaurantes | N38: 152.92 | O38: 46158
A39: lavadora | B39: Mudanza | D39: 333.67 | F39: Careem | G39: Delivery | I39: 41.99 | K39: Careem varios | L39: Delivery | N39: 92.39 | O39: 46159
A40: cama y bed sheets | B40: Mudanza | D40: 84 | F40: Careem | G40: Delivery | I40: 5.36 | K40: Careem varios | L40: Delivery | N40: 36.47 | O40: 46160
A41: toallas | B41: Mudanza | D41: 57.72 | F41: Careem | G41: Delivery | I41: 52.02 | K41: du | L41: Suministros piso | N41: 14.33 | O41: 46161
A42: colchon | B42: Mudanza | D42: 370.78 | F42: Ikea | G42: Mudanza | I42: 426.48 | K42: Careem varios | L42: Delivery | N42: 92.58 | O42: 46163
A43: ikea sartenes | B43: Mudanza | D43: 71.8 | F43: Loocitane | G43: Bea | I43: 11.59 | K43: Aeropuert Dubai | L43: Compras | N43: 109.08 | O43: 46164
...

Sheet Junio
A1: INGRESOS MENSUALES
A2: Concepto | C2: Total AED | D2: Total EUR | F2: 6697 | G2: =F2*Resumen!$D$1 -> 1607.28
A3: Salario Santi | C3: 24194.44 | D3: =C3*Resumen!$D$1 -> 5806.6656 | F3: =G3/Resumen!$D$1 -> 1875 | G3: 450
A4: Salario Bea | C4: =D4/Resumen!$D$1 -> 13450 | D4: 3228 | F4: =G4/Resumen!$D$1 -> 5383.875 | G4: 1292.13
A5: Ingresos extra | C5: =D5/Resumen!$D$1 -> 1875 | D5: 450 | F5: =G5/Resumen!$D$1 -> 682.70833 | G5: 163.85
A6: TOTAL INGRESOS | C6: =SUM(C3:C5) -> 39519.44 | D6: =SUM(D3:D5) -> 9484.6656 | F6: =SUM(F2:F5) -> 14638.583 | G6: =SUM(G2:G5) -> 3513.26 | H6: ahorrado este mes a 24 jun | J6: lo que tenemos en cuentas
A7: BALANCE (Ingreso - Gasto) | D7: =D6-E32 -> 79.6036
F8: 8000 | G8: =F8*Resumen!$D$1 -> 1920 | H8: alquiler mes
A9: GASTOS MENSUALES
G10: =G6-G8 -> 1593.26 | H10: ahorrado real con piso pagado
A11: RESUMEN POR CATEGORÍA
A12: Categoría | B12: Nº Gastos | C12: Total AED | D12: Total EUR
A13: Restaurantes | B13: =COUNTIF($B$37:$B$99,A13)+COUNTIF($G$37:$G$56,A13)+COUNTIF($L$37:$L$56,A13)+COUNTIF($Q$37:$Q$56,A13)+COUNTIF($V$37:$V$56,A13) -> 16 | C13: =SUMIF($B$37:$B$100,A13,$C$37:$C$100)+SUMIF($G$37:$G$100,A13,$H$37:$H$100)+SUMIF($L$37:$L$100,A13,$M$37:$M$100)+SUMIF($Q$37:$Q$100,A13,$R$37:$R$100)+SUMIF($V$37:$V$100,A13,$W$37:$W$100) -> 1983 | D13: =SUMIF($B$37:$B$100,A13,$D$37:$D$100)+SUMIF($G$37:$G$100,A13,$I$37:$I$100)+SUMIF($L$37:$L$100,A13,$N$37:$N$100)+SUMIF($Q$37:$Q$100,A13,$S$37:$S$100)+SUMIF($V$37:$V$100,A13,$X$37:$X$100) -> 452.76
